Workbook
Name _4164_1: 'DMR 001C NEW'!$A$2:$M$704
Name _4165_1: 'DMR Flows-Effluent'!$A$2:$F$72
Name drilldown: 'DMR 001C NEW'!$XBC$2:$XBC$704
Name drilldown: 'DMR Flows-Effluent'!$XBA$2:$XBA$72

Sheet S
A1: Sheet Name | B1: Start Cell | C1: End Cell | D1: BusinessArea Name | E1: ReportGroup Name | F1: Report Name | G1: Parameters | H1: Rows | I1: User Id | J1: BusinessArea Id | K1: ReportGroup Id | L1: Report Id | M1: Headers | N1: Pivot Sheet Name Ref | O1: Sheet Name Ref | Q1: Process Id | R1: Splash SessionID | S1: Status | T1: Pivot Sheet Name | U1: Old ProcessId | V1: ColumnsCount | W1: Download Time | X1: Error Message | Z1: MandatoryParameters | AA1: Json ParameterString | AB1: StartTime | AC1: EndTime | AD1: UserGroup ID | AE1: IsModifyReport | AG1: Modify Report JSON
A2: DMR 001C NEW | B2: A1 | D2: MWRD | E2: MWRD Regulatory | F2: DMR 001C NEW | G2: Sample Date==Custom,2019-07-28,2019-08-31^^Loccode=="6I","2B","4B","6","1002B","1004B","2I","4I"^^Acode=="DO","PH","ECIDX","TCL2A","NH3A","NO5","CBOD","TSS","VISSH","$IMSTW","$ICPM","$IMSPD","HGLL","$ICAN","$PERC1","$VOC","$NONP","WCNM","$ICPDC","$ICPT1","FTR","TCN","TCN1","TLTMW","HGCVW","PHE","$MET2","TCNM","$CDCR3","$CHFH5","XHEM","HEXGR","HEXHC","$VOC1"^^Anlname=="Dissolved Oxygen, Probe","pH","E-Coli, MPN Idexx Colilert","Tot. Chlorine Residual","Ammonia Nitrogen, AA","CBOD, 5-Day","Total Suspended Solids","Visible Sheen, (Grease)","Arsenic, Tot.","Arsenic, Pot. Diss.","Cadmium, Pot. Diss.","Cadmium, Tot.","Chromium, Tot.","Copper, Diss.","Copper, Pot. Diss.","Cyanide, WeakAcid, Man. Dist","Iron, Diss.","Iron, Tot.","Lead, Diss.","Lead, Pot. Diss.","Lead, Tot.","Manganese, Tot.","Molybdenum, Tot.","Mercury, Tot., Low Level","Nickel, Tot.","Nickel, Pot. Diss.","Selenium, Pot. Diss.","Silver, Pot. Diss.","Zinc, Pot. Diss.","Chloride","Sulfate","Nonylphenol","NO3+NO2 as N - Cd Red.","Flow to the River","Cyanide, Tot.","Beryllium, Tot.","Copper, Tot.","Thallium, Tot., ICPMS","Silver, Tot.","Zinc, Tot.","Mercury, Tot., Cold Vapor","Antimony, Tot.","Selenium, Tot.","Phenol, Manual Distill, AA","Thallium","Cyanide, Tot., Manual","IC25 Reproduction","IC25 Biomass","NOEC Reproduction","NOEC Biomass","Tetrachloroethene","Thallium, Tot.","Hexane Extractables","Hexane Hydrocarbons Extr."^^Acquired Type==^^ | H2: 702 | I2: 21 | J2: 5 | K2: 22 | L2: 635 | M2: Y | O2: ='DMR 001C NEW'!VST1 -> 0 | Q2: 4164 | R2: 0 | S2: 11 | T2: (P)DMR 001C NEW | U2: 4164_1 | V2: 15 | W2: 43724.435 | X2: The file is not existed in the server | AA2: [{"dataType":"DATE","displayType":"DR","dateRange":"Custom","endDateRange":"2019-08-31","parameterName":"Sample Date","parameterValue":null,"startDateRange":"2019-07-28","dateFormat":"yyyy-MM-dd","originalDataType":null},{"dataType":"TEXT","displayType":"DD","dateRange":null,"endDateRange":null,"parameterName":"Loccode","parameterValue":"\"6I\",\"2B\",\"4B\",\"6\",\"1002B\",\"1004B\",\"2I\",\"4I\"","startDateRange":null,"dateFormat":null,"originalDataType":"TEXT"},{"dataType":"TEXT","displayType":"DD","dateRange":null,"endDateRange":null,"parameterName":"Acode","parameterValue":"\"DO\",\"PH\",\"ECIDX\",\"TCL2A\",\"NH3A\",\"NO5\",\"CBOD\",\"TSS\",\"VISSH\",\"$IMSTW\",\"$ICPM\",\"$IMSPD\",\"HGLL\",\"$ICAN\",\"$PERC1\",\"$VOC\",\"$NONP\",\"WCNM\",\"$ICPDC\",\"$ICPT1\",\"FTR\",\"TCN\",\"TCN1\",\"TLTMW\",\"HGCVW\",\"PHE\",\"$MET2\",\"TCNM\",\"$CDCR3\",\"$CHFH5\",\"XHEM\",\"HEXGR\",\"HEXHC\",\"$VOC1\"","startDateRange":null,"dateFormat":null,"originalDataType":"TEXT"},{"dataType":"TEXT","displayType":"DD","dateRange":null,"endDateRange":null,"parameterName":"Anlname","parameterValue":"\"Dissolved Oxygen, Probe\",\"pH\",\"E-Coli, MPN Idexx Colilert\",\"Tot. Chlorine Residual\",\"Ammonia Nitrogen, AA\",\"CBOD, 5-Day\",\"Total Suspended Solids\",\"Visible Sheen, (Grease)\",\"Arsenic, Tot.\",\"Arsenic, Pot. Diss.\",\"Cadmium, Pot. Diss.\",\"Cadmium, Tot.\",\"Chromium, Tot.\",\"Copper, Diss.\",\"Copper, Pot. Diss.\",\"Cyanide, WeakAcid, Man. Dist\",\"Iron, Diss.\",\"Iron, Tot.\",\"Lead, Diss.\",\"Lead, Pot. Diss.\",\"Lead, Tot.\",\"Manganese, Tot.\",\"Molybdenum, Tot.\",\"Mercury, Tot., Low Level\",\"Nickel, Tot.\",\"Nickel, Pot. Diss.\",\"Selenium, Pot. Diss.\",\"Silver, Pot. Diss.\",\"Zinc, Pot. Diss.\",\"Chloride\",\"Sulfate\",\"Nonylphenol\",\"NO3+NO2 as N - Cd Red.\",\"Flow to the River\",\"Cyanide, Tot.\",\"Beryllium, Tot.\",\"Copper, Tot.\",\"Thallium, Tot., ICPMS\",\"Silver, Tot.\",\"Zinc, Tot.\",\"Mercury, Tot., Cold Vapor\",\"Antimony, Tot.\",\"Selenium, Tot.\",\"Phenol, Manual Distill, AA\",\"Thallium\",\"Cyanide, Tot., Manual\",\"IC25 Reproduction\",\"IC25 Biomass\",\"NOEC Reproduction\",\"NOEC Biomass\",\"Tetrachloroethene\",\"Thallium, Tot.\",\"Hexane Extractables\",\"Hexane Hydrocarbons Extr.\"","startDateRange":null,"dateFormat":null,"originalDataType":"TEXT"},{"dataType":"TEXT","displayType":"DD","dateRange":null,"endDateRange":null,"parameterName":"Acquired Type","parameterValue":null,"startDateRange":null,"dateFormat":null,"originalDataType":"TEXT"}] | AB2: 43724.435 | AC2: 43724.435 | AE2: 0 | AF2: null | AH2: Pivot | AJ2: Pivot | AL2: Pivot | AN2: Pivot | AP2: Pivot | AR2: Pivot | AT2: Pivot | AV2: Pivot | AX2: Pivot | AZ2: Pivot | BB2: Pivot | BD2: Pivot | BF2: Pivot | BH2: Pivot | BJ2: Pivot | BL2: Pivot | BN2: Pivot | BP2: Pivot | BR2: Pivot | BT2: Pivot | BV2: Pivot | BX2: Pivot | BZ2: Pivot | CB2: Pivot | CD2: Pivot | CF2: Pivot | CH2: Pivot | CJ2: Pivot | CL2: Pivot | CN2: Pivot | CP2: Pivot | CR2: Pivot | CT2: D0N Totals
A3: DMR Flows-Effluent | B3: A1 | D3: MWRD | E3: MWRD Regulatory | F3: DMR Flows-Effluent | G3: Tag=="FI-F4","FI-F350"^^Isexcluded==^^Trunc Date==Custom,2019-07-28,2019-08-31^^ | H3: 70 | I3: 21 | J3: 5 | K3: 22 | L3: 622 | M3: Y | O3: ='DMR Flows-Effluent'!VSR1 -> 0 | Q3: 4165 | R3: 0 | S3: 11 | T3: (P)DMR Flows-Effluent | U3: 4165_1 | V3: 7 | W3: 43724.436 | X3: The file is not existed in the server | AA3: [{"dataType":"TEXT","displayType":"DD","dateRange":null,"endDateRange":null,"parameterName":"Tag","parameterValue":"\"FI-F4\",\"FI-F350\"","startDateRange":null,"dateFormat":null,"originalDataType":"TEXT"},{"dataType":"NUMBER","displayType":"DD","dateRange":null,"endDateRange":null,"parameterName":"Isexcluded","parameterValue":null,"startDateRange":null,"dateFormat":null,"originalDataType":"NUMBER"},{"dataType":"DATE","displayType":"DR","dateRange":"Custom","endDateRange":"2019-08-31","parameterName":"Trunc Date","parameterValue":null,"startDateRange":"2019-07-28","dateFormat":null,"originalDataType":null}] | AB3: 43724.436 | AC3: 43724.436 | AE3: 0 | AF3: null | AH3: Pivot | AJ3: Pivot | AL3: Pivot | AN3: Pivot | AP3: Pivot | AR3: Pivot | AT3: Pivot | AV3: Pivot | AX3: Pivot | AZ3: Pivot | BB3: Pivot | BD3: Pivot | BF3: Pivot | BH3: Pivot | BJ3: Pivot | BL3: Pivot | BN3: Pivot | BP3: Pivot | BR3: Pivot | BT3: Pivot | BV3: Pivot | BX3: Pivot | BZ3: Pivot | CB3: Pivot | CD3: Pivot | CF3: Pivot | CH3: Pivot | CJ3: Pivot | CL3: Pivot | CN3: Pivot | CP3: Pivot | CR3: Pivot | CT3: DF Totals

Sheet CSV-Monthly
A1: permit_id | B1: permitted_feature_id | C1: limit_set_txt | D1: mped_txt | E1: form_nodi_cd | F1: parameter_cd | G1: monitoring_location_cd | H1: season_num | I1: quant_1_nodi_cd | J1: quant_1_qualifier_txt | K1: quant_1_sample_num | L1: quant_1_effluent_num | M1: quant_2_nodi_cd | N1: quant_2_qualifier_txt | O1: quant_2_sample_num | P1: quant_2_effluent_num | Q1: quant_uom_cd | R1: conc_1_nodi_cd | S1: conc_1_qualifier_txt | T1: conc_1_sample_num | U1: conc_1_effluent_num | V1: conc_2_nodi_cd | W1: conc_2_qualifier_txt | X1: conc_2_sample_num | Y1: conc_2_effluent_num | Z1: conc_3_nodi_cd | AA1: conc_3_qualifier_txt | AB1: conc_3_sample_num | AC1: conc_3_effluent_num | AD1: conc_uom_cd | AE1: excursions_num | AF1: freq_analysis_cd | AG1: sample_type_cd | AH1: param_nodi_cd | AI1: comment_txt
A2: CO0026638 | B2: 001 | C2: C | D2: ='001-C DMR'!$B$2 -> 43708 | F2: 00300 | G2: 1 | H2: 0 | S2: = | T2: ='001-C DMR'!I51 -> 5.9885775 | W2: = | X2: ='001-C DMR'!J53 -> 6.1824812 | AE2: ='001-C DMR'!K56 -> 0 | AF2: ='001-C DMR'!K55 -> 07/WK | AG2: GR
A3: CO0026638 | B3: 001 | C3: C | D3: ='001-C DMR'!$B$2 -> 43708 | F3: 00400 | G3: 1 | H3: 0 | S3: = | T3: ='001-C DMR'!X54 -> 6.909448 | AA3: = | AB3: ='001-C DMR'!X53 -> 7.1 | AE3: ='001-C DMR'!T56 -> 0 | AF3: ='001-C DMR'!T55 -> 07/WK | AG3: GR
A4: CO0026638 | B4: 001 | C4: C | D4: ='001-C DMR'!$B$2 -> 43708 | F4: 00530 | G4: 1 | H4: 0 | W4: = | X4: ='001-C DMR'!AH49 -> 12.150826 | AA4: = | AB4: ='001-C DMR'!AI52 -> 14.784939 | AE4: ='001-C DMR'!AJ56 -> 0 | AF4: ='001-C DMR'!AJ55 -> 07/WK | AG4: CP
A5: CO0026638 | B5: 001 | C5: C | D5: ='001-C DMR'!$B$2 -> 43708 | F5: 00610 | G5: 1 | H5: ='001-C DMR'!$B$4 -> 8 | W5: ='001-C DMR'!AW49 -> = | X5: ='001-C DMR'!AY49 -> 0.95515286 | AA5: = | AB5: {='001-C DMR'!AY50} -> 1.8646593 | AE5: 0 | AF5: ='001-C DMR'!AZ55 -> 03/07 | AG5: CP
A6: CO0026638 | B6: 001 | C6: C | D6: ='001-C DMR'!$B$2 -> 43708 | F6: 00630 | G6: 1 | H6: ='001-C DMR'!$B$4 -> 8 | AA6: ='001-C DMR'!BM50 -> = | AB6: ='001-C DMR'!BO50 -> 6.2372256 | AE6: ='001-C DMR'!BP56 -> 0 | AF6: ='001-C DMR'!BP55 -> 03/07 | AG6: CP
A7: CO0026638 | B7: 001 | C7: C | D7: ='001-C DMR'!$B$2 -> 43708 | F7: 00640 | G7: 1 | H7: 0 | AG7: CP
A8: CO0026638 | B8: 001 | C8: C | D8: ='001-C DMR'!$B$2 -> 43708 | F8: 00665 | G8: 1 | H8: 0 | AG8: CP
A9: CO0026638 | B9: 001 | C9: C | D9: ='001-C DMR'!$B$2 -> 43708 | F9: 00940 | G9: 1 | H9: 0 | W9: ='001-C DMR'!CD49 -> = | X9: ='001-C DMR'!CE49 -> 101.37998 | AE9: ='001-C DMR'!CF56 -> 0 | AF9: ='001-C DMR'!CF55 -> 01/07 | AG9: CP
A10: CO0026638 | B10: 001 | C10: C | D10: ='001-C DMR'!$B$2 -> 43708 | F10: 00980 | G10: 1 | H10: 0 | W10: ='001-C DMR'!CN49 -> = | X10: ='001-C DMR'!CO49 -> 238 | AE10: ='001-C DMR'!CQ56 -> 0 | AF10: ='001-C DMR'!CQ55 -> 01/07 | AG10: CP
A11: CO0026638 | B11: 001 | C11: C | D11: ='001-C DMR'!$B$2 -> 43708 | F11: 01046 | G11: 1 | H11: 0 | W11: ='001-C DMR'!CN49 -> = | X11: ='001-C DMR'!DA49 -> 60.6 | AE11: ='001-C DMR'!DQ56 -> 0 | AF11: ='001-C DMR'!DC55 -> 01/07 | AG11: CP
A12: CO0026638 | B12: 001 | C12: C | D12: ='001-C DMR'!$B$2 -> 43708 | F12: 01313 | G12: 1 | H12: =IF('001-C DMR'!B4=VALUE(6),"1","0") -> 0 | J12: ='001-C DMR'!$DO$49 -> = | K12: ='001-C DMR'!$DP$49 -> 0.1301841 | W12: ='001-C DMR'!DL49 -> = | X12: ='001-C DMR'!DM49 -> 0.126 | AA12: ='001-C DMR'!DL50 -> = | AB12: ='001-C DMR'!DM50 -> 0.15 | AE12: ='001-C DMR'!DQ56 -> 0 | AF12: ='001-C DMR'!DQ55 -> 01/07 | AG12: CP
A13: CO0026638 | B13: 001 | C13: C | D13: ='001-C DMR'!$B$2 -> 43708 | F13: 03582 | G13: 1 | H13: 0 | W13: ='001-C DMR'!EF50 -> < | X13: ='001-C DMR'!EG50 -> 5.4 | AE13: 0 | AF13: ='001-C DMR'!EH55 -> 77/77 | AG13: GR
A14: CO0026638 | B14: 001 | C14: C | D14: ='001-C DMR'!$B$2 -> 43708 | F14: 50050 | G14: 1 | H14: 0 | J14: ='001-C DMR'!EJ49 -> = | K14: ='001-C DMR'!EK49 -> 123.88575 | N14: ='001-C DMR'!EJ50 -> = | O14: ='001-C DMR'!EK50 -> 134.761 | AE14: ='001-C DMR'!EK56 -> 0 | AF14: ='001-C DMR'!EK55 -> 99/99 | AG14: RC
A15: CO0026638 | B15: 001 | C15: C | D15: ='001-C DMR'!$B$2 -> 43708 | F15: 50060 | G15: 1 | H15: 0 | AG15: GR | AH15: ='001-C DMR'!EO57 -> 9 | AI15: NCT
A16: CO0026638 | B16: 001 | C16: C | D16: ='001-C DMR'!$B$2 -> 43708 | F16: 51040 | G16: 1 | H16: 0 | W16: ='001-C DMR'!EP49 -> = | X16: ='001-C DMR'!EQ49 -> 106.14691 | AA16: ='001-C DMR'!EQ52 -> = | AB16: ='001-C DMR'!ER52 -> 121.97291 | AE16: ='001-C DMR'!ES56 -> 0 | AF16: ='001-C DMR'!ES55 -> 0 | AG16: GR
A17: CO0026638 | B17: 001 | C17: C | D17: ='001-C DMR'!$B$2 -> 43708 | F17: 51568 | G17: 1 | H17: 0 | W17: ='001-C DMR'!EU49 -> < | X17: ='001-C DMR'!EV49 -> 2.76 | AA17: ='001-C DMR'!EU50 -> < | AB17: ='001-C DMR'!EV50 -> 2.76 | AE17: ='001-C DMR'!EX56 -> 0 | AF17: ='001-C DMR'!EX55 -> 01/30 | AG17: GR
A18: CO0026638 | B18: 001 | C18: C | D18: ='001-C DMR'!$B$2 -> 43708 | F18: 80082 | G18: 1 | H18: 0 | W18: ='001-C DMR'!FK49 -> = | X18: ='001-C DMR'!FL49 -> 4.4323609 | AA18: ='001-C DMR'!FL52 -> = | AB18: ='001-C DMR'!FM52 -> 5.1045548 | AE18: ='001-C DMR'!FN56 -> 0 | AF18: ='001-C DMR'!FN55 -> 06/07 | AG18: CP
A19: CO0026638 | B19: 001 | C19: C | D19: ='001-C DMR'!$B$2 -> 43708 | F19: 80091 | G19: K | H19: 0 | S19: = | T19: ='001-C DMR'!FO49 -> 97.767682 | AE19: 0 | AF19: ='001-C DMR'!FO55 -> 01/30 | AG19: CA
A20: CO0026638 | B20: 001 | C20: C | D20: ='001-C DMR'!$B$2 -> 43708 | F20: 81011 | G20: K | H20: 0 | S20: = | T20: ='001-C DMR'!FV49 -> 96.12261 | AE20: 0 | AF20: ='001-C DMR'!FV55 -> 01/30 | AG20: CA
A21: CO0026638 | B21: 001 | C21: C | D21: ='001-C DMR'!$B$2 -> 43708 | F21: 81020 | G21: 1 | H21: 0 | W21: ='001-C DMR'!GB49 -> = | X21: ='001-C DMR'!GC49 -> 117.46792 | AE21: ='001-C DMR'!GD56 -> 0 | AF21: ='001-C DMR'!GD55 -> 01/07 | AG21: CP
A22: CO0026638 | B22: 001 | C22: C | D22: ='001-C DMR'!$B$2 -> 43708 | F22: 84066 | G22: 1 | H22: 0 | N22: ='001-C DMR'!GL50 -> = | O22: ='001-C DMR'!GM50 -> 0 | AE22: ='001-C DMR'!GN56 -> 0 | AF22: ='001-C DMR'!GN55 -> 07/WK | AG22: VI

Sheet 001-C DMR
A1: Period Start | B1: =B3-WEEKDAY(B3-1) -> 43674
A2: Period End | B2: =EOMONTH(B3,0) -> 43708
A3: Month | B3: 43678
A4: Month | B4: =MONTH(B3) -> 8
A5: Days in Month | B5: =DAY(EOMONTH(B3,0)) -> 31
A6: 001-C | C6: Dissolved Oxygen, Probe | L6: DO Check | R6: pH | U6: pH Check | AB6: Total Suspended Solids | AK6: TSS Check | AQ6: Ammonia Nitrogen, AA | BA6: Ammonia Check | BG6: NO3+NO2 as N - Cd Red. | BQ6: NO5 Check | BW6: TIN | BX6: Phosphorus | BY6: Chloride | CG6: chloride check | CM6: Iron, Tot. | CR6: Fe (total) check | CY6: Iron, Diss. | DD6: Iron (Diss) check | DK6: Cadmium, Pot. Diss. | DR6: Cd (PD) Check | DY6: Hexane Hydrocarbons Extr. | EI6: Flow | EL6: TRC | EP6: E-Coli, MPN Idexx Colilert | ET6: Nonylphenol | EY6: Nonylphenol check | FF6: CBOD, 5-Day | FO6: CBOD % removal | FP6: CBOD Check | FV6: TSS % Removal | FW6: Sulfate | GE6: sulfate check | GK6: Visible Sheen, (Grease)
R7: 00400 | AB7: 00530 | AQ7: 00610 | BG7: 00630 | BW7: 00640 | BX7: 00665 | BY7: 00940 | CM7: 00980 | CY7: 01046 | DK7: 01313 | DY7: 03582 | EI7: 50050 | EL7: 50060 | EP7: 51040 | ET7: 51568 | FF7: 80082 | FO7: 80091 | FV7: 81011 | FW7: 81020 | GK7: 84066
A8: Limits | C8: 3 | D8: 5 | R8: 6 | S8: 9 | AB8: 30 | AC8: 45 | AQ8: {=INDEX(Parameters!$A$23:$D$34,MATCH('001-C DMR'!$B$4,(Parameters!$A$23:$A$34),0),MATCH('001-C DMR'!$A$49:$B$49,Parameters!$A$22:$D$22,0))} -> 3.2 | AR8: {=INDEX(Parameters!$A$23:$D$34,MATCH('001-C DMR'!$B$4,(Parameters!$A$23:$A$34),0),MATCH($A$50,Parameters!$A$22:$D$22,0))} -> 7.9 | BG8: {=INDEX(Parameters!$A$36:$D$47,MATCH('001-C DMR'!$B$4,(Parameters!$A$36:$A$47),0),MATCH('001-C DMR'!$A$50:$B$50,Parameters!$A$35:$D$35,0))} -> 10 | BY8: Report | CM8: Report | CY8: Report | DK8: Report | DP8: {=INDEX(Parameters!$A$49:$D$60,MATCH('001-C DMR'!$B$4,(Parameters!$A$49:$A$60),0),MATCH('001-C DMR'!$A$49:$B$49,Parameters!$A$48:$D$48,0))} -> 1.12 | EI8: Average | EJ8: Tag | EL8: 0.011 | EM8: 0.019 | EN8: mg/L | EP8: 126 | EQ8: 252 | ET8: Report | FF8: 17 | FG8: 25 | FW8: Report
A9: SS | C9: N/A | R9: N/A | AB9: 5 | AC9: mg/L | AQ9: 0.2 | AR9: mg/L | BG9: 0.1 | BH9: mg/L | BW9: 0.2 | BX9: 0.05 | BY9: 2 | BZ9: mg/L | CM9: 20 | CN9: ug/L | CY9: 20 | CZ9: ug/L | DK9: 0.5 | DL9: ug/L | EL9: 0.05 | EM9: mg/L | ET9: 10 | EU9: ug/L | FF9: 2 | FG9: mg/L | FW9: 2 mg/L
A10: Location Code | C10: 2B | F10: 4B | L10: 6 | M10: 6I | N10: 1002B | O10: 1004B | P10: 2I | Q10: 4I | R10: 6 | U10: 6I | V10: 1002B | W10: 1004B | X10: 2B | Y10: 4B | Z10: 2I | AA10: 4I | AB10: 2B | AE10: 4B | AK10: 6I | AL10: 1002B | AM10: 1004B | AN10: 6 | AO10: 2I | AP10: 4I | AQ10: 1002B | AU10: 1004B | BA10: 6I | BB10: 2B | BC10: 4B | BD10: 6 | BE10: 2I | BF10: 4I | BG10: 1002B | BK10: 1004B | BQ10: 6I | BR10: 2B | BS10: 4B | BT10: 6 | BU10: 2I | BV10: 4I | BY10: 2B | CB10: 4B | CG10: 6 | CH10: 6I | CI10: 1002B | CJ10: 1004B | CK10: 2I | CL10: 4I | CM10: 6 | CR10: 2B | CS10: 4B | CT10: 1002B | CU10: 1004B | CV10: 6I | CW10: 2I | CX10: 4I | CY10: 6 | DD10: 2B | DE10: 4B | DF10: 1002B | DG10: 1004B | DH10: 6I | DI10: 2I | DJ10: 4I | DK10: 6 | DR10: 2B | DS10: 4B | DT10: 1002B | DU10: 1004B | DV10: 6I | DW10: 2I | DX10: 4I | DY10: 2I | EC10: 4I | EI10: FI-F350 | EJ10: FI-F4 | EP10: CFE | ET10: 6I | EY10: 6 | EZ10: 2B | FA10: 4B | FB10: 1002B | FC10: 1004B | FD10: 2I | FE10: 4I | FF10: 2B | FI10: 4B | FP10: 6I | FQ10: 1002B | FR10: 1004B | FS10: 6 | FT10: 2I | FU10: 4I | FW10: 2B | FZ10: 4B | GE10: 6 | GF10: 6I | GG10: 1002B | GH10: 1004B | GI10: 2I | GJ10: 4I | GK10: 2B | GL10: 4B | GM10: FW | GN10: Count
A11: Day | B11: Date | C11: Result | D11: Sampno | E11: Flow to the River | F11: Result | G11: Samplenumber | H11: Flow to the River | I11: Flow weighted | J11: 7 day average | K11: Count | L11: Result | R11: Mdlcomparison | S11: Result | T11: Count | U11: Result | AB11: Mdl comparison | AC11: ML | AD11: Result | AE11: Mdlcomparison | AF11: ML | AG11: Result | AH11: Flow weighted | AI11: 7 day average | AJ11: count | AK11: Result | AQ11: Mdl comparison | AR11: ML | AS11: Result | AT11: computing result | AU11: Mdl comparison | AV11: ML | AW11: Result | AX11: computing result | AY11: Flow weighted | AZ11: Count | BA11: Result | BG11: Mdl comparison | BH11: ML | BI11: Result | BJ11: computing result | BK11: Mdl comparison | BL11: ML | BM11: Result | BN11: computing result | BO11: Flow weighted | BP11: Count | BQ11: Result | BY11: Mdl comparison | BZ11: ML | CA11: Result | CB11: Mdl comparison | CC11: ML | CD11: Result | CE11: Flow weighted | CF11: Count | CG11: Result | CM11: Mdl comparison | CN11: ML | CO11: Result | CP11: computing result | CQ11: Count | CR11: Result | CY11: Mdl comparison | CZ11: ML | DA11: Result | DB11: computing result | DC11: Count | DK11: Mdl comparison | DL11: ML | DM11: Result | DN11: computing result | DO11: Mdlcomparison | DP11: Lbs/Day | DQ11: Count | DR11: Result | DY11: Mdl comparison | DZ11: ML | EA11: Result | EB11: computing result | EC11: Mdl comparison | ED11: ML | EE11: Result | EF11: computing result | EG11: Flow weighted | EH11: Count | EI11: North | EJ11: South | EK11: Total | EL11: North | EM11: South | EN11: Flow Weighted | EO11: Count | EP11: Mdlcomparison | EQ11: CFE | ER11: 7 day average | ES11: Count | ET11: Mdl comparison | EU11: ML | EV11: Result | EW11: Computing Result | EX11: count | EY11: Result | FF11: Mdl comparison | FG11: ML | FH11: Result | FI11: Mdl comparison | FJ11: ML | FK11: Result | FL11: Flow weighted | FM11: 7 day average | FN11: count | FP11: Result | FW11: Mdl comparison | FX11: ML | FY11: Result | FZ11: Mdl comparison | GA11: ML | GB11: Result | GC11: Flow weighted | GD11: Count | GE11: Result | GK11: Result | GL11: Result
A12: =TEXT(B12,"ddd") -> Sun | B12: =B1 -> 43674 | C12: {=INDEX('DMR 001C NEW'!$A$3:$N$10020,MATCH(('001-C DMR'!$C$6:$K$6&'001-C DMR'!$C$10:$E$10&'001-C DMR'!$B12),('DMR 001C NEW'!$E$3:$E$7246&'DMR 001C NEW'!$B$3:$B$7246&'DMR 001C NEW'!$A$3:$A$7246),0),MATCH('001-C DMR'!$C$11,'DMR 001C NEW'!$A$2:$O$2,0))} -> 5.9 | D12: {=INDEX('DMR 001C NEW'!$A$3:$N$11771,MATCH(('001-C DMR'!$C$6:$K$6&'001-C DMR'!$C$10:$E$10&'001-C DMR'!$B12),('DMR 001C NEW'!$E$3:$E$9018&'DMR 001C NEW'!$B$3:$B$9018&'DMR 001C NEW'!$A$3:$A$9018),0),MATCH('001-C DMR'!$D$11,'DMR 001C NEW'!$A$2:$O$2,0))} -> AE67427 | E12: {=INDEX('DMR 001C NEW'!$A$3:$N$9999,MATCH(('001-C DMR'!$E$11&'001-C DMR'!$C$10:$E$10&'001-C DMR'!$B12&$D12),('DMR 001C NEW'!$E$3:$E$7246&'DMR 001C NEW'!$B$3:$B$7246&'DMR 001C NEW'!$A$3:$A$7246&'DMR 001C NEW'!$M$3:$M$7188),0),MATCH($C$11,'DMR 001C NEW'!$A$2:$O$2,0))} -> 40.92 | F12: {=INDEX('DMR 001C NEW'!$A$3:$N$9999,MATCH('001-C DMR'!$C$6:$K$6&'001-C DMR'!$F$10&'001-C DMR'!$B12,('DMR 001C NEW'!$E$3:$E$7246&'DMR 001C NEW'!$B$3:$B$7246&'DMR 001C NEW'!$A$3:$A$7246),0),MATCH('001-C DMR'!$C$11,'DMR 001C NEW'!$A$2:$O$2,0))} -> 6.7 | G12: {=INDEX('DMR 001C NEW'!$A$3:$N$9999,MATCH(('001-C DMR'!$C$6:$K$6&'001-C DMR'!$F$10&'001-C DMR'!$B12),('DMR 001C NEW'!$E$3:$E$7246&'DMR 001C NEW'!$B$3:$B$7246&'DMR 001C NEW'!$A$3:$A$7246),0),MATCH('001-C DMR'!$D$11,'DMR 001C NEW'!$A$2:$O$2,0))} -> AE67428 | H12: {=INDEX('DMR 001C NEW'!$A$3:$N$9999,MATCH(('001-C DMR'!$E$11&'001-C DMR'!$F$10&'001-C DMR'!$B12&$G12),('DMR 001C NEW'!$E$3:$E$7246&'DMR 001C NEW'!$B$3:$B$7246&'DMR 001C NEW'!$A$3:$A$7246&'DMR 001C NEW'!$M$3:$M$7188),0),MATCH($C$11,'DMR 001C NEW'!$A$2:$O$2,0))} -> 53.26 | I12: =(($C12*$E12)+($F12*$H12))/($H12+$E12) -> 6.3524103 | J12: =IF($A12="Sat",(AVERAGE(I12)),"") | K12: =IF($A12="Sat",COUNT(I5:I12),"") | L12: {=_xlfn.IFNA(INDEX('DMR 001C NEW'!$A$3:$N$3865,MATCH(('001-C DMR'!$C$6:$K$6&'001-C DMR'!L$10&'001-C DMR'!$B12),('DMR 001C NEW'!$E$3:$E$1112&'DMR 001C NEW'!$B$3:$B$1112&'DMR 001C NEW'!$A$3:$A$1112),0),MATCH('001-C DMR'!$C$11,'DMR 001C NEW'!$A$2:$O$2,0)),"")} | M12: {=_xlfn.IFNA(INDEX('DMR 001C NEW'!$A$3:$N$3865,MATCH(('001-C DMR'!$C$6:$K$6&'001-C DMR'!M$10&'001-C DMR'!$B12),('DMR 001C NEW'!$E$3:$E$1112&'DMR 001C NEW'!$B$3:$B$1112&'DMR 001C NEW'!$A$3:$A$1112),0),MATCH('001-C DMR'!$C$11,'DMR 001C NEW'!$A$2:$O$2,0)),"")} | N12: {=_xlfn.IFNA(INDEX('DMR 001C NEW'!$A$3:$N$3865,MATCH(('001-C DMR'!$C$6:$K$6&'001-C DMR'!N$10&'001-C DMR'!$B12),('DMR 001C NEW'!$E$3:$E$1112&'DMR 001C NEW'!$B$3:$B$1112&'DMR 001C NEW'!$A$3:$A$1112),0),MATCH('001-C DMR'!$C$11,'DMR 001C NEW'!$A$2:$O$2,0)),"")} | O12: {=_xlfn.IFNA(INDEX('DMR 001C NEW'!$A$3:$N$3865,MATCH(('001-C DMR'!$C$6:$K$6&'001-C DMR'!O$10&'001-C DMR'!$B12),('DMR 001C NEW'!$E$3:$E$1112&'DMR 001C NEW'!$B$3:$B$1112&'DMR 001C NEW'!$A$3:$A$1112),0),MATCH('001-C DMR'!$C$11,'DMR 001C NEW'!$A$2:$O$2,0)),"")} | P12: {=_xlfn.IFNA(INDEX('DMR 001C NEW'!$A$3:$N$3865,MATCH(('001-C DMR'!$C$6:$K$6&'001-C DMR'!P$10&'001-C DMR'!$B12),('DMR 001C NEW'!$E$3:$E$1112&'DMR 001C NEW'!$B$3:$B$1112&'DMR 001C NEW'!$A$3:$A$1112),0),MATCH('001-C DMR'!$C$11,'DMR 001C NEW'!$A$2:$O$2,0)),"")} | Q12: {=INDEX('DMR 001C NEW'!$A$3:$N$3865,MATCH(('001-C DMR'!$C$6:$K$6&'001-C DMR'!Q$10&'001-C DMR'!$B12),('DMR 001C NEW'!$E$3:$E$1112&'DMR 001C NEW'!$B$3:$B$1112&'DMR 001C NEW'!$A$3:$A$1112),0),MATCH('001-C DMR'!$C$11,'DMR 001C NEW'!$A$2:$O$2,0))} -> #N/A | S12: {=_xlfn.IFNA(INDEX('DMR 001C NEW'!$A$3:$N$11771,MATCH(('001-C DMR'!$R$6:$T$6&'001-C DMR'!$R$10&'001-C DMR'!$B12),('DMR 001C NEW'!$E$3:$E$9018&'DMR 001C NEW'!$B$3:$B$9018&'DMR 001C NEW'!$A$3:$A$9018),0),MATCH('001-C DMR'!$S$11,'DMR 001C NEW'!$A$2:$O$2,0)),"")} -> 7 | U12: {=_xlfn.IFNA(INDEX('DMR 001C NEW'!$A$3:$O$591,MATCH('001-C DMR'!$R$6:$T$6&'001-C DMR'!U$10&'001-C DMR'!$B12,('DMR 001C NEW'!$E$3:$E$704&'DMR 001C NEW'!$B$3:$B$704&'DMR 001C NEW'!$A$3:$A$704),0),MATCH('001-C DMR'!$U$11,'DMR 001C NEW'!$A$2:$O$2,0)),"")} | V12: {=_xlfn.IFNA(INDEX('DMR 001C NEW'!$A$3:$O$591,MATCH('001-C DMR'!$R$6:$T$6&'001-C DMR'!V$10&'001-C DMR'!$B12,('DMR 001C NEW'!$E$3:$E$704&'DMR 001C NEW'!$B$3:$B$704&'DMR 001C NEW'!$A$3:$A$704),0),MATCH('001-C DMR'!$U$11,'DMR 001C NEW'!$A$2:$O$2,0)),"")} | W12: {=_xlfn.IFNA(INDEX('DMR 001C NEW'!$A$3:$O$591,MATCH('001-C DMR'!$R$6:$T$6&'001-C DMR'!W$10&'001-C DMR'!$B12,('DMR 001C NEW'!$E$3:$E$704&'DMR 001C NEW'!$B$3:$B$704&'DMR 001C NEW'!$A$3:$A$704),0),MATCH('001-C DMR'!$U$11,'DMR 001C NEW'!$A$2:$O$2,0)),"")} | X12: {=_xlfn.IFNA(INDEX('DMR 001C NEW'!$A$3:$O$591,MATCH('001-C DMR'!$R$6:$T$6&'001-C DMR'!X$10&'001-C DMR'!$B12,('DMR 001C NEW'!$E$3:$E$704&'DMR 001C NEW'!$B$3:$B$704&'DMR 001C NEW'!$A$3:$A$704),0),MATCH('001-C DMR'!$U$11,'DMR 001C NEW'!$A$2:$O$2,0)),"")} | Y12: {=_xlfn.IFNA(INDEX('DMR 001C NEW'!$A$3:$O$591,MATCH('001-C DMR'!$R$6:$T$6&'001-C DMR'!Y$10&'001-C DMR'!$B12,('DMR 001C NEW'!$E$3:$E$704&'DMR 001C NEW'!$B$3:$B$704&'DMR 001C NEW'!$A$3:$A$704),0),MATCH('001-C DMR'!$U$11,'DMR 001C NEW'!$A$2:$O$2,0)),"")} | Z12: {=_xlfn.IFNA(INDEX('DMR 001C NEW'!$A$3:$O$591,MATCH('001-C DMR'!$R$6:$T$6&'001-C DMR'!Z$10&'001-C DMR'!$B12,('DMR 001C NEW'!$E$3:$E$704&'DMR 001C NEW'!$B$3:$B$704&'DMR 001C NEW'!$A$3:$A$704),0),MATCH('001-C DMR'!$U$11,'DMR 001C NEW'!$A$2:$O$2,0)),"")} | AA12: {=_xlfn.IFNA(INDEX('DMR 001C NEW'!$A$3:$O$591,MATCH('001-C DMR'!$R$6:$T$6&'001-C DMR'!AA$10&'001-C DMR'!$B12,('DMR 001C NEW'!$E$3:$E$704&'DMR 001C NEW'!$B$3:$B$704&'DMR 001C NEW'!$A$3:$A$704),0),MATCH('001-C DMR'!$U$11,'DMR 001C NEW'!$A$2:$O$2,0)),"")} | AB12: {=IF(AD12<AC12,"<","")} | AC12: {=_xlfn.IFNA(INDEX('DMR 001C NEW'!$A$3:$O$9999,MATCH(('001-C DMR'!$AB$6:$AJ$6&'001-C DMR'!$AB$10:$AD$10&'001-C DMR'!$B12),('DMR 001C NEW'!$E$3:$E$7246&'DMR 001C NEW'!$B$3:$B$7246&'DMR 001C NEW'!$A$3:$A$7246),0),MATCH('001-C DMR'!$AC$11,'DMR 001C NEW'!$A$2:$O$2,0)),"")} -> 3 | AD12: {=_xlfn.IFNA(INDEX('DMR 001C NEW'!$A$3:$O$9999,MATCH(('001-C DMR'!$AB$6:$AJ$6&'001-C DMR'!$AB$10:$AD$10&'001-C DMR'!$B12),('DMR 001C NEW'!$E$3:$E$7246&'DMR 001C NEW'!$B$3:$B$7246&'DMR 001C NEW'!$A$3:$A$7246),0),MATCH('001-C DMR'!$AD$11,'DMR 001C NEW'!$A$2:$O$2,0)),"")} -> 9 | AE12: {=IF(AG12<AF12,"<","")} | AF12: {=_xlfn.IFNA(INDEX('DMR 001C NEW'!$A$3:$O$9999,MATCH(('001-C DMR'!$AB$6:$AJ$6&'001-C DMR'!$AE$10&'001-C DMR'!$B12),('DMR 001C NEW'!$E$3:$E$9018&'DMR 001C NEW'!$B$3:$B$9018&'DMR 001C NEW'!$A$3:$A$9018),0),MATCH('001-C DMR'!$AF$11,'DMR 001C NEW'!$A$2:$O$2,0)),"")} -> 3 | AG12: {=_xlfn.IFNA(INDEX('DMR 001C NEW'!$A$3:$O$9999,MATCH(('001-C DMR'!$AB$6:$AJ$6&'001-C DMR'!$AE$10&'001-C DMR'!$B12),('DMR 001C NEW'!$E$3:$E$9018&'DMR 001C NEW'!$B$3:$B$9018&'DMR 001C NEW'!$A$3:$A$9018),0),MATCH('001-C DMR'!$AG$11,'DMR 001C NEW'!$A$2:$O$2,0)),"")} -> 10 | AH12: {=IFERROR((($AD12*$EI12)+($AG12*$EJ12))/($EK12),"")} -> 9.5656024 | AI12: =IF($A12="Sat",(AVERAGE(AH12)),"") | AJ12: =IF($A12="Sat",COUNT(AH5:AH12),"") | AK12: {=_xlfn.IFNA(INDEX('DMR 001C NEW'!$A$3:$O$999,MATCH(('001-C DMR'!$AB$6:$AJ$6&'001-C DMR'!AK$10&'001-C DMR'!$B12),('DMR 001C NEW'!$E$3:$E$1112&'DMR 001C NEW'!$B$3:$B$1112&'DMR 001C NEW'!$A$3:$A$1112),0),MATCH('001-C DMR'!$AD$11,'DMR 001C NEW'!$A$2:$O$2,0)),"")} | AL12: {=_xlfn.IFNA(INDEX('DMR 001C NEW'!$A$3:$O$999,MATCH(('001-C DMR'!$AB$6:$AJ$6&'001-C DMR'!AL$10&'001-C DMR'!$B12),('DMR 001C NEW'!$E$3:$E$1112&'DMR 001C NEW'!$B$3:$B$1112&'DMR 001C NEW'!$A$3:$A$1112),0),MATCH('001-C DMR'!$AD$11,'DMR 001C NEW'!$A$2:$O$2,0)),"")} | AM12: {=_xlfn.IFNA(INDEX('DMR 001C NEW'!$A$3:$O$999,MATCH(('001-C DMR'!$AB$6:$AJ$6&'001-C DMR'!AM$10&'001-C DMR'!$B12),('DMR 001C NEW'!$E$3:$E$1112&'DMR 001C NEW'!$B$3:$B$1112&'DMR 001C NEW'!$A$3:$A$1112),0),MATCH('001-C DMR'!$AD$11,'DMR 001C NEW'!$A$2:$O$2,0)),"")} | AN12: {=_xlfn.IFNA(INDEX('DMR 001C NEW'!$A$3:$O$999,MATCH(('001-C DMR'!$AB$6:$AJ$6&'001-C DMR'!AN$10&'001-C DMR'!$B12),('DMR 001C NEW'!$E$3:$E$1112&'DMR 001C NEW'!$B$3:$B$1112&'DMR 001C NEW'!$A$3:$A$1112),0),MATCH('001-C DMR'!$AD$11,'DMR 001C NEW'!$A$2:$O$2,0)),"")} | AO12: {=_xlfn.IFNA(INDEX('DMR 001C NEW'!$A$3:$O$999,MATCH(('001-C DMR'!$AB$6:$AJ$6&'001-C DMR'!AO$10&'001-C DMR'!$B12),('DMR 001C NEW'!$E$3:$E$1112&'DMR 001C NEW'!$B$3:$B$1112&'DMR 001C NEW'!$A$3:$A$1112),0),MATCH('001-C DMR'!$AD$11,'DMR 001C NEW'!$A$2:$O$2,0)),"")} | AP12: {=_xlfn.IFNA(INDEX('DMR 001C NEW'!$A$3:$O$999,MATCH(('001-C DMR'!$AB$6:$AJ$6&'001-C DMR'!AP$10&'001-C DMR'!$B12),('DMR 001C NEW'!$E$3:$E$1112&'DMR 001C NEW'!$B$3:$B$1112&'DMR 001C NEW'!$A$3:$A$1112),0),MATCH('001-C DMR'!$AD$11,'DMR 001C NEW'!$A$2:$O$2,0)),"")} | AQ12: {=IF(AS12<AR12,"<","")} | AR12: {=_xlfn.IFNA((INDEX('DMR 001C NEW'!$A$3:$O$9999,MATCH(('001-C DMR'!$AQ$6:$AZ$6&'001-C DMR'!$AQ$10:$AS$10&'001-C DMR'!$B12),('DMR 001C NEW'!$E$3:$E$7246&'DMR 001C NEW'!$B$3:$B$7246&'DMR 001C NEW'!$A$3:$A$7246),0),MATCH('001-C DMR'!$AR$11,'DMR 001C NEW'!$A$2:$O$2,0))),"")} -> 0.15 | AS12: {=_xlfn.IFNA(INDEX('DMR 001C NEW'!$A$3:$O$9999,MATCH(('001-C DMR'!$AQ$6:$AZ$6&'001-C DMR'!$AQ$10:$AS$10&'001-C DMR'!$B12),('DMR 001C NEW'!$E$3:$E$7246&'DMR 001C NEW'!$B$3:$B$7246&'DMR 001C NEW'!$A$3:$A$7246),0),MATCH('001-C DMR'!$AS$11,'DMR 001C NEW'!$A$2:$O$2,0)),"")} -> 0.94 | AT12: =IF(AS12<AR12,0,AS12) -> 0.94 | AU12: {=IF(AW12<AV12,"<","")} -> < | AV12: {=_xlfn.IFNA((INDEX('DMR 001C NEW'!$A$3:$O$9999,MATCH(('001-C DMR'!$AQ$6:$AZ$6&'001-C DMR'!$AU$10&'001-C DMR'!$B12),('DMR 001C NEW'!$E$3:$E$7246&'DMR 001C NEW'!$B$3:$B$7246&'DMR 001C NEW'!$A$3:$A$7246),0),MATCH('001-C DMR'!$AR$11,'DMR 001C NEW'!$A$2:$O$2,0))),"")} -> 0.15 | AW12: {=_xlfn.IFNA(INDEX('DMR 001C NEW'!$A$3:$O$9999,MATCH(('001-C DMR'!$AQ$6:$AZ$6&'001-C DMR'!$AU$10&'001-C DMR'!$B12),('DMR 001C NEW'!$E$3:$E$7246&'DMR 001C NEW'!$B$3:$B$7246&'DMR 001C NEW'!$A$3:$A$7246),0),MATCH('001-C DMR'!$AW$11,'DMR 001C NEW'!$A$2:$O$2,0)),"")} -> 0.13 | AX12: =IF(AW12<AV12,0,AW12) -> 0 | AY12: {=IFERROR((($AT12*$EI12)+($AX12*$EJ12))/($EK12),"")} -> 0.40833373 | AZ12: =IF($A12="Sat",COUNT(AW5:AW12),"") | BA12: {=_xlfn.IFNA(INDEX('DMR 001C NEW'!$A$3:$O$9999,MATCH(('001-C DMR'!$AQ$6:$AZ$6&'001-C DMR'!BA$10&'001-C DMR'!$B12),('DMR 001C NEW'!$E$3:$E$1112&'DMR 001C NEW'!$B$3:$B$1112&'DMR 001C NEW'!$A$3:$A$1112),0),MATCH('001-C DMR'!$BA$11,'DMR 001C NEW'!$A$2:$O$2,0)),"")} | BB12: {=_xlfn.IFNA(INDEX('DMR 001C NEW'!$A$3:$O$9999,MATCH(('001-C DMR'!$AQ$6:$AZ$6&'001-C DMR'!BB$10&'001-C DMR'!$B12),('DMR 001C NEW'!$E$3:$E$1112&'DMR 001C NEW'!$B$3:$B$1112&'DMR 001C NEW'!$A$3:$A$1112),0),MATCH('001-C DMR'!$BA$11,'DMR 001C NEW'!$A$2:$O$2,0)),"")} | BC12: {=_xlfn.IFNA(INDEX('DMR 001C NEW'!$A$3:$O$9999,MATCH(('001-C DMR'!$AQ$6:$AZ$6&'001-C DMR'!BC$10&'001-C DMR'!$B12),('DMR 001C NEW'!$E$3:$E$1112&'DMR 001C NEW'!$B$3:$B$1112&'DMR 001C NEW'!$A$3:$A$1112),0),MATCH('001-C DMR'!$BA$11,'DMR 001C NEW'!$A$2:$O$2,0)),"")} | BD12: {=_xlfn.IFNA(INDEX('DMR 001C NEW'!$A$3:$O$9999,MATCH(('001-C DMR'!$AQ$6:$AZ$6&'001-C DMR'!BD$10&'001-C DMR'!$B12),('DMR 001C NEW'!$E$3:$E$1112&'DMR 001C NEW'!$B$3:$B$1112&'DMR 001C NEW'!$A$3:$A$1112),0),MATCH('001-C DMR'!$BA$11,'DMR 001C NEW'!$A$2:$O$2,0)),"")} | BE12: {=_xlfn.IFNA(INDEX('DMR 001C NEW'!$A$3:$O$9999,MATCH(('001-C DMR'!$AQ$6:$AZ$6&'001-C DMR'!BE$10&'001-C DMR'!$B12),('DMR 001C NEW'!$E$3:$E$1112&'DMR 001C NEW'!$B$3:$B$1112&'DMR 001C NEW'!$A$3:$A$1112),0),MATCH('001-C DMR'!$BA$11,'DMR 001C NEW'!$A$2:$O$2,0)),"")} | BF12: {=_xlfn.IFNA(INDEX('DMR 001C NEW'!$A$3:$O$9999,MATCH(('001-C DMR'!$AQ$6:$AZ$6&'001-C DMR'!BF$10&'001-C DMR'!$B12),('DMR 001C NEW'!$E$3:$E$1112&'DMR 001C NEW'!$B$3:$B$1112&'DMR 001C NEW'!$A$3:$A$1112),0),MATCH('001-C DMR'!$BA$11,'DMR 001C NEW'!$A$2:$O$2,0)),"")} | BG12: =IF(BI12<BH12,"<","") | BH12: {=_xlfn.IFNA((INDEX('DMR 001C NEW'!$A$3:$O$9999,MATCH(('001-C DMR'!$BG$6&'001-C DMR'!$BG$10&'001-C DMR'!$B12),('DMR 001C NEW'!$E$3:$E$7246&'DMR 001C NEW'!$B$3:$B$7246&'DMR 001C NEW'!$A$3:$A$7246),0),MATCH('001-C DMR'!$BH$11,'DMR 001C NEW'!$A$2:$O$2,0))),"")} -> 0.06 | BI12: {=_xlfn.IFNA(INDEX('DMR 001C NEW'!$A$3:$O$9999,MATCH(('001-C DMR'!$BG$6&'001-C DMR'!$BG$10&'001-C DMR'!$B12),('DMR 001C NEW'!$E$3:$E$7246&'DMR 001C NEW'!$B$3:$B$7246&'DMR 001C NEW'!$A$3:$A$7246),0),MATCH('001-C DMR'!$BI$11,'DMR 001C NEW'!$A$2:$O$2,0)),"")} -> 4.28 | BJ12: =IF(BI12<BH12,0,BI12) -> 4.28 | BK12: =IF(BM12<BL12,"<","") | BL12: {=_xlfn.IFNA((INDEX('DMR 001C NEW'!$A$3:$O$9999,MATCH(('001-C DMR'!$BG$6&'001-C DMR'!$BK$10&'001-C DMR'!$B12),('DMR 001C NEW'!$E$3:$E$7246&'DMR 001C NEW'!$B$3:$B$7246&'DMR 001C NEW'!$A$3:$A$7246),0),MATCH('001-C DMR'!$BH$11,'DMR 001C NEW'!$A$2:$O$2,0))),"")} -> 0.06 | BM12: {=_xlfn.IFNA(INDEX('DMR 001C NEW'!$A$3:$O$9999,MATCH(('001-C DMR'!$BG$6&'001-C DMR'!$BK$10&'001-C DMR'!$B12),('DMR 001C NEW'!$E$3:$E$7246&'DMR 001C NEW'!$B$3:$B$7246&'DMR 001C NEW'!$A$3:$A$7246),0),MATCH('001-C DMR'!$BI$11,'DMR 001C NEW'!$A$2:$O$2,0)),"")} -> 6.53 | BN12: =IF(BM12<BL12,0,BM12) -> 6.53 | BO12: {=IFERROR((($BJ12*$EI12)+($BN12*$EJ12))/($EK12),"")} -> 5.5526054 | BP12: =IF($A12="Sat",COUNT(BM5:BM12),"") | BQ12: {=_xlfn.IFNA(INDEX('DMR 001C NEW'!$A$3:$O$999,MATCH(('001-C DMR'!$BG$6&'001-C DMR'!BQ$10&'001-C DMR'!$B12),('DMR 001C NEW'!$E$3:$E$1112&'DMR 001C NEW'!$B$3:$B$1112&'DMR 001C NEW'!$A$3:$A$1112),0),MATCH('001-C DMR'!$BQ$11,'DMR 001C NEW'!$A$2:$O$2,0)),"")} | BR12: {=_xlfn.IFNA(INDEX('DMR 001C NEW'!$A$3:$O$999,MATCH(('001-C DMR'!$BG$6&'001-C DMR'!BR$10&'001-C DMR'!$B12),('DMR 001C NEW'!$E$3:$E$1112&'DMR 001C NEW'!$B$3:$B$1112&'DMR 001C NEW'!$A$3:$A$1112),0),MATCH('001-C DMR'!$BQ$11,'DMR 001C NEW'!$A$2:$O$2,0)),"")} | BS12: {=_xlfn.IFNA(INDEX('DMR 001C NEW'!$A$3:$O$999,MATCH(('001-C DMR'!$BG$6&'001-C DMR'!BS$10&'001-C DMR'!$B12),('DMR 001C NEW'!$E$3:$E$1112&'DMR 001C NEW'!$B$3:$B$1112&'DMR 001C NEW'!$A$3:$A$1112),0),MATCH('001-C DMR'!$BQ$11,'DMR 001C NEW'!$A$2:$O$2,0)),"")} | BT12: {=_xlfn.IFNA(INDEX('DMR 001C NEW'!$A$3:$O$999,MATCH(('001-C DMR'!$BG$6&'001-C DMR'!BT$10&'001-C DMR'!$B12),('DMR 001C NEW'!$E$3:$E$1112&'DMR 001C NEW'!$B$3:$B$1112&'DMR 001C NEW'!$A$3:$A$1112),0),MATCH('001-C DMR'!$BQ$11,'DMR 001C NEW'!$A$2:$O$2,0)),"")} | BU12: {=_xlfn.IFNA(INDEX('DMR 001C NEW'!$A$3:$O$999,MATCH(('001-C DMR'!$BG$6&'001-C DMR'!BU$10&'001-C DMR'!$B12),('DMR 001C NEW'!$E$3:$E$1112&'DMR 001C NEW'!$B$3:$B$1112&'DMR 001C NEW'!$A$3:$A$1112),0),MATCH('001-C DMR'!$BQ$11,'DMR 001C NEW'!$A$2:$O$2,0)),"")} | BV12: {=_xlfn.IFNA(INDEX('DMR 001C NEW'!$A$3:$O$999,MATCH(('001-C DMR'!$BG$6&'001-C DMR'!BV$10&'001-C DMR'!$B12),('DMR 001C NEW'!$E$3:$E$1112&'DMR 001C NEW'!$B$3:$B$1112&'DMR 001C NEW'!$A$3:$A$1112),0),MATCH('001-C DMR'!$BQ$11,'DMR 001C NEW'!$A$2:$O$2,0)),"")} | BY12: =IF(CA12<BZ12,"<","") | BZ12: {=_xlfn.IFNA((INDEX('DMR 001C NEW'!$A$3:$O$9999,MATCH(('001-C DMR'!$BY$6&'001-C DMR'!$BY$10&'001-C DMR'!$B12),('DMR 001C NEW'!$E$3:$E$7246&'DMR 001C NEW'!$B$3:$B$7246&'DMR 001C NEW'!$A$3:$A$7246),0),MATCH('001-C DMR'!$BZ$11,'DMR 001C NEW'!$A$2:$O$2,0))),"")} | CA12: {=_xlfn.IFNA(INDEX('DMR 001C NEW'!$A$3:$O$9999,MATCH(('001-C DMR'!$BY$6&'001-C DMR'!$BY$10&'001-C DMR'!$B12),('DMR 001C NEW'!$E$3:$E$7246&'DMR 001C NEW'!$B$3:$B$7246&'DMR 001C NEW'!$A$3:$A$7246),0),MATCH('001-C DMR'!$CA$11,'DMR 001C NEW'!$A$2:$O$2,0)),"")} | CB12: =IF(CD12<CC12,"<","") | CC12: {=_xlfn.IFNA((INDEX('DMR 001C NEW'!$A$3:$O$9999,MATCH(('001-C DMR'!$BY$6&'001-C DMR'!$CB$10&'001-C DMR'!$B12),('DMR 001C NEW'!$E$3:$E$7246&'DMR 001C NEW'!$B$3:$B$7246&'DMR 001C NEW'!$A$3:$A$7246),0),MATCH('001-C DMR'!$BZ$11,'DMR 001C NEW'!$A$2:$O$2,0))),"")} | CD12: {=_xlfn.IFNA(INDEX('DMR 001C NEW'!$A$3:$O$9999,MATCH(('001-C DMR'!$BY$6&'001-C DMR'!$CB$10&'001-C DMR'!$B12),('DMR 001C NEW'!$E$3:$E$7246&'DMR 001C NEW'!$B$3:$B$7246&'DMR 001C NEW'!$A$3:$A$7246),0),MATCH('001-C DMR'!$CA$11,'DMR 001C NEW'!$A$2:$O$2,0)),"")} | CE12: {=IFERROR((($CA12*$EI12)+($CD12*$EJ12))/($EK12),"")} | CF12: =IF($A12="Sat",COUNT(CE5:CE12),"") | CG12: {=_xlfn.IFNA(INDEX('DMR 001C NEW'!$A$3:$O$999,MATCH(('001-C DMR'!$BY$6&'001-C DMR'!CG$10&'001-C DMR'!$B12),('DMR 001C NEW'!$E$3:$E$1112&'DMR 001C NEW'!$B$3:$B$1112&'DMR 001C NEW'!$A$3:$A$1112),0),MATCH('001-C DMR'!$CA$11,'DMR 001C NEW'!$A$2:$O$2,0)),"")} | CH12: {=_xlfn.IFNA(INDEX('DMR 001C NEW'!$A$3:$O$999,MATCH(('001-C DMR'!$BY$6&'001-C DMR'!CH$10&'001-C DMR'!$B12),('DMR 001C NEW'!$E$3:$E$1112&'DMR 001C NEW'!$B$3:$B$1112&'DMR 001C NEW'!$A$3:$A$1112),0),MATCH('001-C DMR'!$CA$11,'DMR 001C NEW'!$A$2:$O$2,0)),"")} | CI12: {=_xlfn.IFNA(INDEX('DMR 001C NEW'!$A$3:$O$999,MATCH(('001-C DMR'!$BY$6&'001-C DMR'!CI$10&'001-C DMR'!$B12),('DMR 001C NEW'!$E$3:$E$1112&'DMR 001C NEW'!$B$3:$B$1112&'DMR 001C NEW'!$A$3:$A$1112),0),MATCH('001-C DMR'!$CA$11,'DMR 001C NEW'!$A$2:$O$2,0)),"")} | CJ12: {=_xlfn.IFNA(INDEX('DMR 001C NEW'!$A$3:$O$999,MATCH(('001-C DMR'!$BY$6&'001-C DMR'!CJ$10&'001-C DMR'!$B12),('DMR 001C NEW'!$E$3:$E$1112&'DMR 001C NEW'!$B$3:$B$1112&'DMR 001C NEW'!$A$3:$A$1112),0),MATCH('001-C DMR'!$CA$11,'DMR 001C NEW'!$A$2:$O$2,0)),"")} | CK12: {=_xlfn.IFNA(INDEX('DMR 001C NEW'!$A$3:$O$999,MATCH(('001-C DMR'!$BY$6&'001-C DMR'!CK$10&'001-C DMR'!$B12),('DMR 001C NEW'!$E$3:$E$1112&'DMR 001C NEW'!$B$3:$B$1112&'DMR 001C NEW'!$A$3:$A$1112),0),MATCH('001-C DMR'!$CA$11,'DMR 001C NEW'!$A$2:$O$2,0)),"")} | CL12: {=_xlfn.IFNA(INDEX('DMR 001C NEW'!$A$3:$O$999,MATCH(('001-C DMR'!$BY$6&'001-C DMR'!CL$10&'001-C DMR'!$B12),('DMR 001C NEW'!$E$3:$E$1112&'DMR 001C NEW'!$B$3:$B$1112&'DMR 001C NEW'!$A$3:$A$1112),0),MATCH('001-C DMR'!$CA$11,'DMR 001C NEW'!$A$2:$O$2,0)),"")} | CM12: =IF(CO12<CN12,"<","") | CN12: {=_xlfn.IFNA((INDEX('DMR 001C NEW'!$A$3:$O$9999,MATCH(('001-C DMR'!$CM$6&'001-C DMR'!$CM$10&'001-C DMR'!$B12),('DMR 001C NEW'!$E$3:$E$9018&'DMR 001C NEW'!$B$3:$B$9018&'DMR 001C NEW'!$A$3:$A$9018),0),MATCH('001-C DMR'!$CN$11,'DMR 001C NEW'!$A$2:$O$2,0))*1000),"")} | CO12: {=_xlfn.IFNA(INDEX('DMR 001C NEW'!$A$3:$O$9999,MATCH(('001-C DMR'!$CM$6&'001-C DMR'!$CM$10&'001-C DMR'!$B12),('DMR 001C NEW'!$E$3:$E$9018&'DMR 001C NEW'!$B$3:$B$9018&'DMR 001C NEW'!$A$3:$A$9018),0),MATCH('001-C DMR'!$CO$11,'DMR 001C NEW'!$A$2:$O$2,0))*1000,"")} | CP12: =IF(CO12<CN12,0,CO12) | CQ12: =IF($A12="Sat",COUNT(CO5:CO12),"") | CR12: {=_xlfn.IFNA(INDEX('DMR 001C NEW'!$A$3:$O$999,MATCH(('001-C DMR'!$CM$6&'001-C DMR'!CR$10&'001-C DMR'!$B12),('DMR 001C NEW'!$E$3:$E$1112&'DMR 001C NEW'!$B$3:$B$1112&'DMR 001C NEW'!$A$3:$A$1112),0),MATCH('001-C DMR'!$CO$11,'DMR 001C NEW'!$A$2:$O$2,0)),"")} | CS12: {=_xlfn.IFNA(INDEX('DMR 001C NEW'!$A$3:$O$999,MATCH(('001-C DMR'!$CM$6&'001-C DMR'!CS$10&'001-C DMR'!$B12),('DMR 001C NEW'!$E$3:$E$1112&'DMR 001C NEW'!$B$3:$B$1112&'DMR 001C NEW'!$A$3:$A$1112),0),MATCH('001-C DMR'!$CO$11,'DMR 001C NEW'!$A$2:$O$2,0)),"")} | CT12: {=_xlfn.IFNA(INDEX('DMR 001C NEW'!$A$3:$O$999,MATCH(('001-C DMR'!$CM$6&'001-C DMR'!CT$10&'001-C DMR'!$B12),('DMR 001C NEW'!$E$3:$E$1112&'DMR 001C NEW'!$B$3:$B$1112&'DMR 001C NEW'!$A$3:$A$1112),0),MATCH('001-C DMR'!$CO$11,'DMR 001C NEW'!$A$2:$O$2,0)),"")} | CU12: {=_xlfn.IFNA(INDEX('DMR 001C NEW'!$A$3:$O$999,MATCH(('001-C DMR'!$CM$6&'001-C DMR'!CU$10&'001-C DMR'!$B12),('DMR 001C NEW'!$E$3:$E$1112&'DMR 001C NEW'!$B$3:$B$1112&'DMR 001C NEW'!$A$3:$A$1112),0),MATCH('001-C DMR'!$CO$11,'DMR 001C NEW'!$A$2:$O$2,0)),"")} | CV12: {=_xlfn.IFNA(INDEX('DMR 001C NEW'!$A$3:$O$999,MATCH(('001-C DMR'!$CM$6&'001-C DMR'!CV$10&'001-C DMR'!$B12),('DMR 001C NEW'!$E$3:$E$1112&'DMR 001C NEW'!$B$3:$B$1112&'DMR 001C NEW'!$A$3:$A$1112),0),MATCH('001-C DMR'!$CO$11,'DMR 001C NEW'!$A$2:$O$2,0)),"")} | CW12: {=_xlfn.IFNA(INDEX('DMR 001C NEW'!$A$3:$O$999,MATCH(('001-C DMR'!$CM$6&'001-C DMR'!CW$10&'001-C DMR'!$B12),('DMR 001C NEW'!$E$3:$E$1112&'DMR 001C NEW'!$B$3:$B$1112&'DMR 001C NEW'!$A$3:$A$1112),0),MATCH('001-C DMR'!$CO$11,'DMR 001C NEW'!$A$2:$O$2,0)),"")} | CX12: {=_xlfn.IFNA(INDEX('DMR 001C NEW'!$A$3:$O$999,MATCH(('001-C DMR'!$CM$6&'001-C DMR'!CX$10&'001-C DMR'!$B12),('DMR 001C NEW'!$E$3:$E$1112&'DMR 001C NEW'!$B$3:$B$1112&'DMR 001C NEW'!$A$3:$A$1112),0),MATCH('001-C DMR'!$CO$11,'DMR 001C NEW'!$A$2:$O$2,0)),"")} | CY12: =IF(DA12<CZ12,"<","") | CZ12: {=_xlfn.IFNA((INDEX('DMR 001C NEW'!$A$3:$O$9999,MATCH(('001-C DMR'!$CY$6&'001-C DMR'!$CY$10&'001-C DMR'!$B12),('DMR 001C NEW'!$E$3:$E$9018&'DMR 001C NEW'!$B$3:$B$9018&'DMR 001C NEW'!$A$3:$A$9018),0),MATCH('001-C DMR'!$CZ$11,'DMR 001C NEW'!$A$2:$O$2,0))*1000),"")} | DA12: {=_xlfn.IFNA(INDEX('DMR 001C NEW'!$A$3:$O$9999,MATCH(('001-C DMR'!$CY$6&'001-C DMR'!$CY$10&'001-C DMR'!$B12),('DMR 001C NEW'!$E$3:$E$9018&'DMR 001C NEW'!$B$3:$B$9018&'DMR 001C NEW'!$A$3:$A$9018),0),MATCH('001-C DMR'!$DA$11,'DMR 001C NEW'!$A$2:$O$2,0))*1000,"")} | DB12: =IF(DA12<CZ12,0,DA12) | DC12: =IF($A12="Sat",COUNT(DA5:DA12),"") | DD12: {=_xlfn.IFNA(INDEX('DMR 001C NEW'!$A$3:$O$999,MATCH(('001-C DMR'!$CY$6&'001-C DMR'!DD$10&'001-C DMR'!$B12),('DMR 001C NEW'!$E$3:$E$1112&'DMR 001C NEW'!$B$3:$B$1112&'DMR 001C NEW'!$A$3:$A$1112),0),MATCH('001-C DMR'!$DA$11,'DMR 001C NEW'!$A$2:$O$2,0)),"")} | DE12: {=_xlfn.IFNA(INDEX('DMR 001C NEW'!$A$3:$O$999,MATCH(('001-C DMR'!$CY$6&'001-C DMR'!DE$10&'001-C DMR'!$B12),('DMR 001C NEW'!$E$3:$E$1112&'DMR 001C NEW'!$B$3:$B$1112&'DMR 001C NEW'!$A$3:$A$1112),0),MATCH('001-C DMR'!$DA$11,'DMR 001C NEW'!$A$2:$O$2,0)),"")} | DF12: {=_xlfn.IFNA(INDEX('DMR 001C NEW'!$A$3:$O$999,MATCH(('001-C DMR'!$CY$6&'001-C DMR'!DF$10&'001-C DMR'!$B12),('DMR 001C NEW'!$E$3:$E$1112&'DMR 001C NEW'!$B$3:$B$1112&'DMR 001C NEW'!$A$3:$A$1112),0),MATCH('001-C DMR'!$DA$11,'DMR 001C NEW'!$A$2:$O$2,0)),"")} | DG12: {=_xlfn.IFNA(INDEX('DMR 001C NEW'!$A$3:$O$999,MATCH(('001-C DMR'!$CY$6&'001-C DMR'!DG$10&'001-C DMR'!$B12),('DMR 001C NEW'!$E$3:$E$1112&'DMR 001C NEW'!$B$3:$B$1112&'DMR 001C NEW'!$A$3:$A$1112),0),MATCH('001-C DMR'!$DA$11,'DMR 001C NEW'!$A$2:$O$2,0)),"")} | DH12: {=_xlfn.IFNA(INDEX('DMR 001C NEW'!$A$3:$O$999,MATCH(('001-C DMR'!$CY$6&'001-C DMR'!DH$10&'001-C DMR'!$B12),('DMR 001C NEW'!$E$3:$E$1112&'DMR 001C NEW'!$B$3:$B$1112&'DMR 001C NEW'!$A$3:$A$1112),0),MATCH('001-C DMR'!$DA$11,'DMR 001C NEW'!$A$2:$O$2,0)),"")} | DI12: {=_xlfn.IFNA(INDEX('DMR 001C NEW'!$A$3:$O$999,MATCH(('001-C DMR'!$CY$6&'001-C DMR'!DI$10&'001-C DMR'!$B12),('DMR 001C NEW'!$E$3:$E$1112&'DMR 001C NEW'!$B$3:$B$1112&'DMR 001C NEW'!$A$3:$A$1112),0),MATCH('001-C DMR'!$DA$11,'DMR 001C NEW'!$A$2:$O$2,0)),"")} | DJ12: {=_xlfn.IFNA(INDEX('DMR 001C NEW'!$A$3:$O$999,MATCH(('001-C DMR'!$CY$6&'001-C DMR'!DJ$10&'001-C DMR'!$B12),('DMR 001C NEW'!$E$3:$E$1112&'DMR 001C NEW'!$B$3:$B$1112&'DMR 001C NEW'!$A$3:$A$1112),0),MATCH('001-C DMR'!$DA$11,'DMR 001C NEW'!$A$2:$O$2,0)),"")} | DK12: =IF(DM12<DL12,"<","") | DL12: {=_xlfn.IFNA((INDEX('DMR 001C NEW'!$A$3:$O$9999,MATCH(('001-C DMR'!$DK$6&'001-C DMR'!$DK$10&'001-C DMR'!$B12),('DMR 001C NEW'!$E$3:$E$9018&'DMR 001C NEW'!$B$3:$B$9018&'DMR 001C NEW'!$A$3:$A$9018),0),MATCH('001-C DMR'!$DL$11,'DMR 001C NEW'!$A$2:$O$2,0))),"")} | DM12: {=_xlfn.IFNA(INDEX('DMR 001C NEW'!$A$3:$O$9999,MATCH(('001-C DMR'!$DK$6&'001-C DMR'!$DK$10&'001-C DMR'!$B12),('DMR 001C NEW'!$E$3:$E$9018&'DMR 001C NEW'!$B$3:$B$9018&'DMR 001C NEW'!$A$3:$A$9018),0),MATCH('001-C DMR'!$DM$11,'DMR 001C NEW'!$A$2:$O$2,0)),"")} | DN12: =IF(DM12="SCRATCHED","",IF(DM12<DL12,0,DM12)) | DQ12: =IF($A12="Sat",COUNT(DM5:DM12),"") | DR12: {=_xlfn.IFNA(INDEX('DMR 001C NEW'!$A$3:$O$999,MATCH(('001-C DMR'!$DK$6&'001-C DMR'!DR$10&'001-C DMR'!$B12),('DMR 001C NEW'!$E$3:$E$1112&'DMR 001C NEW'!$B$3:$B$1112&'DMR 001C NEW'!$A$3:$A$1112),0),MATCH('001-C DMR'!$DR$11,'DMR 001C NEW'!$A$2:$O$2,0)),"")} | DS12: {=_xlfn.IFNA(INDEX('DMR 001C NEW'!$A$3:$O$999,MATCH(('001-C DMR'!$DK$6&'001-C DMR'!DS$10&'001-C DMR'!$B12),('DMR 001C NEW'!$E$3:$E$1112&'DMR 001C NEW'!$B$3:$B$1112&'DMR 001C NEW'!$A$3:$A$1112),0),MATCH('001-C DMR'!$DR$11,'DMR 001C NEW'!$A$2:$O$2,0)),"")} | DT12: {=_xlfn.IFNA(INDEX('DMR 001C NEW'!$A$3:$O$999,MATCH(('001-C DMR'!$DK$6&'001-C DMR'!DT$10&'001-C DMR'!$B12),('DMR 001C NEW'!$E$3:$E$1112&'DMR 001C NEW'!$B$3:$B$1112&'DMR 001C NEW'!$A$3:$A$1112),0),MATCH('001-C DMR'!$DR$11,'DMR 001C NEW'!$A$2:$O$2,0)),"")} | DU12: {=_xlfn.IFNA(INDEX('DMR 001C NEW'!$A$3:$O$999,MATCH(('001-C DMR'!$DK$6&'001-C DMR'!DU$10&'001-C DMR'!$B12),('DMR 001C NEW'!$E$3:$E$1112&'DMR 001C NEW'!$B$3:$B$1112&'DMR 001C NEW'!$A$3:$A$1112),0),MATCH('001-C DMR'!$DR$11,'DMR 001C NEW'!$A$2:$O$2,0)),"")} | DV12: {=_xlfn.IFNA(INDEX('DMR 001C NEW'!$A$3:$O$999,MATCH(('001-C DMR'!$DK$6&'001-C DMR'!DV$10&'001-C DMR'!$B12),('DMR 001C NEW'!$E$3:$E$1112&'DMR 001C NEW'!$B$3:$B$1112&'DMR 001C NEW'!$A$3:$A$1112),0),MATCH('001-C DMR'!$DR$11,'DMR 001C NEW'!$A$2:$O$2,0)),"")} | DW12: {=_xlfn.IFNA(INDEX('DMR 001C NEW'!$A$3:$O$999,MATCH(('001-C DMR'!$DK$6&'001-C DMR'!DW$10&'001-C DMR'!$B12),('DMR 001C NEW'!$E$3:$E$1112&'DMR 001C NEW'!$B$3:$B$1112&'DMR 001C NEW'!$A$3:$A$1112),0),MATCH('001-C DMR'!$DR$11,'DMR 001C NEW'!$A$2:$O$2,0)),"")} | DX12: {=_xlfn.IFNA(INDEX('DMR 001C NEW'!$A$3:$O$999,MATCH(('001-C DMR'!$DK$6&'001-C DMR'!DX$10&'001-C DMR'!$B12),('DMR 001C NEW'!$E$3:$E$1112&'DMR 001C NEW'!$B$3:$B$1112&'DMR 001C NEW'!$A$3:$A$1112),0),MATCH('001-C DMR'!$DR$11,'DMR 001C NEW'!$A$2:$O$2,0)),"")} | DY12: =IF(EA12<DZ12,"<","") | DZ12: {=_xlfn.IFNA((INDEX('DMR 001C NEW'!$A$3:$O$9999,MATCH(('001-C DMR'!$DY$6&'001-C DMR'!$DY$10&'001-C DMR'!$B12),('DMR 001C NEW'!$E$3:$E$9018&'DMR 001C NEW'!$B$3:$B$9018&'DMR 001C NEW'!$A$3:$A$9018),0),MATCH('001-C DMR'!$DZ$11,'DMR 001C NEW'!$A$2:$O$2,0))),"")} | EA12: {=_xlfn.IFNA((INDEX('DMR 001C NEW'!$A$3:$O$9999,MATCH(('001-C DMR'!$DY$6&'001-C DMR'!$DY$10&'001-C DMR'!$B12),('DMR 001C NEW'!$E$3:$E$9018&'DMR 001C NEW'!$B$3:$B$9018&'DMR 001C NEW'!$A$3:$A$9018),0),MATCH('001-C DMR'!$EA$11,'DMR 001C NEW'!$A$2:$O$2,0))),"")} | EB12: {=IF(EA12="SCRATCHED","",IF(EA12<DZ12,0,EA12))} | EC12: =IF(EE12<ED12,"<","") | ED12: {=_xlfn.IFNA((INDEX('DMR 001C NEW'!$A$3:$O$9999,MATCH(('001-C DMR'!$DY$6&'001-C DMR'!$EC$10&'001-C DMR'!$B12),('DMR 001C NEW'!$E$3:$E$9018&'DMR 001C NEW'!$B$3:$B$9018&'DMR 001C NEW'!$A$3:$A$9018),0),MATCH('001-C DMR'!$DZ$11,'DMR 001C NEW'!$A$2:$O$2,0))),"")} | EE12: {=_xlfn.IFNA((INDEX('DMR 001C NEW'!$A$3:$O$9999,MATCH(('001-C DMR'!$DY$6&'001-C DMR'!$EC$10&'001-C DMR'!$B12),('DMR 001C NEW'!$E$3:$E$9018&'DMR 001C NEW'!$B$3:$B$9018&'DMR 001C NEW'!$A$3:$A$9018),0),MATCH('001-C DMR'!$EE$11,'DMR 001C NEW'!$A$2:$O$2,0))),"")} | EF12: =IF(EE12="SCRATCHED","",IF(EE12<ED12,0,EE12)) | EI12: {=_xlfn.IFNA(INDEX('DMR Flows-Effluent'!$A$3:$F$186,MATCH(($EI$10&$B12),('DMR Flows-Effluent'!$B$3:$B$186&'DMR Flows-Effluent'!$A$3:$A$186),0),MATCH($EI$8,'DMR Flows-Effluent'!$A$2:$F$2,0)),"")} -> 54.6066 | EJ12: {=_xlfn.IFNA(INDEX('DMR Flows-Effluent'!$A$3:$F$186,MATCH(($EJ$10&$B12),('DMR Flows-Effluent'!$B$3:$B$186&'DMR Flows-Effluent'!$A$3:$A$186),0),MATCH($EI$8,'DMR Flows-Effluent'!$A$2:$F$2,0)),"")} -> 71.0999 | EK12: =SUM(EI12:EJ12) -> 125.7065 | EQ12: {='E.Coli Calculations'!R6} -> 74.7804 | ES12: =IF($A12="Sat",COUNT(EQ5:EQ12),"") | ET12: =IF(EV12<EU12,"<","") | EU12: {=_xlfn.IFNA((INDEX('DMR 001C NEW'!$A$3:$O$9999,MATCH(('001-C DMR'!$ET$6&'001-C DMR'!$ET$10&'001-C DMR'!$B12),('DMR 001C NEW'!$E$3:$E$9018&'DMR 001C NEW'!$B$3:$B$9018&'DMR 001C NEW'!$A$3:$A$9018),0),MATCH('001-C DMR'!$EU$11,'DMR 001C NEW'!$A$2:$O$2,0))),"")} | EV12: {=_xlfn.IFNA(INDEX('DMR 001C NEW'!$A$3:$O$9999,MATCH(('001-C DMR'!$ET$6&'001-C DMR'!$ET$10&'001-C DMR'!$B12),('DMR 001C NEW'!$E$3:$E$9018&'DMR 001C NEW'!$B$3:$B$9018&'DMR 001C NEW'!$A$3:$A$9018),0),MATCH('001-C DMR'!$EV$11,'DMR 001C NEW'!$A$2:$O$2,0)),"")} | EW12: =IF(EV12="SCRATCHED","",IF(EV12<EU12,0,EV12)) | EY12: {=_xlfn.IFNA(INDEX('DMR 001C NEW'!$A$3:$O$999,MATCH(('001-C DMR'!$ET$6&'001-C DMR'!EY$10&'001-C DMR'!$B12),('DMR 001C NEW'!$E$3:$E$1112&'DMR 001C NEW'!$B$3:$B$1112&'DMR 001C NEW'!$A$3:$A$1112),0),MATCH('001-C DMR'!$EY$11,'DMR 001C NEW'!$A$2:$O$2,0)),"")} | EZ12: {=_xlfn.IFNA(INDEX('DMR 001C NEW'!$A$3:$O$999,MATCH(('001-C DMR'!$ET$6&'001-C DMR'!EZ$10&'001-C DMR'!$B12),('DMR 001C NEW'!$E$3:$E$1112&'DMR 001C NEW'!$B$3:$B$1112&'DMR 001C NEW'!$A$3:$A$1112),0),MATCH('001-C DMR'!$EY$11,'DMR 001C NEW'!$A$2:$O$2,0)),"")} | FA12: {=_xlfn.IFNA(INDEX('DMR 001C NEW'!$A$3:$O$999,MATCH(('001-C DMR'!$ET$6&'001-C DMR'!FA$10&'001-C DMR'!$B12),('DMR 001C NEW'!$E$3:$E$1112&'DMR 001C NEW'!$B$3:$B$1112&'DMR 001C NEW'!$A$3:$A$1112),0),MATCH('001-C DMR'!$EY$11,'DMR 001C NEW'!$A$2:$O$2,0)),"")} | FB12: {=_xlfn.IFNA(INDEX('DMR 001C NEW'!$A$3:$O$999,MATCH(('001-C DMR'!$ET$6&'001-C DMR'!FB$10&'001-C DMR'!$B12),('DMR 001C NEW'!$E$3:$E$1112&'DMR 001C NEW'!$B$3:$B$1112&'DMR 001C NEW'!$A$3:$A$1112),0),MATCH('001-C DMR'!$EY$11,'DMR 001C NEW'!$A$2:$O$2,0)),"")} | FC12: {=_xlfn.IFNA(INDEX('DMR 001C NEW'!$A$3:$O$999,MATCH(('001-C DMR'!$ET$6&'001-C DMR'!FC$10&'001-C DMR'!$B12),('DMR 001C NEW'!$E$3:$E$1112&'DMR 001C NEW'!$B$3:$B$1112&'DMR 001C NEW'!$A$3:$A$1112),0),MATCH('001-C DMR'!$EY$11,'DMR 001C NEW'!$A$2:$O$2,0)),"")} | FD12: {=_xlfn.IFNA(INDEX('DMR 001C NEW'!$A$3:$O$999,MATCH(('001-C DMR'!$ET$6&'001-C DMR'!FD$10&'001-C DMR'!$B12),('DMR 001C NEW'!$E$3:$E$1112&'DMR 001C NEW'!$B$3:$B$1112&'DMR 001C NEW'!$A$3:$A$1112),0),MATCH('001-C DMR'!$EY$11,'DMR 001C NEW'!$A$2:$O$2,0)),"")} | FE12: {=_xlfn.IFNA(INDEX('DMR 001C NEW'!$A$3:$O$999,MATCH(('001-C DMR'!$ET$6&'001-C DMR'!FE$10&'001-C DMR'!$B12),('DMR 001C NEW'!$E$3:$E$1112&'DMR 001C NEW'!$B$3:$B$1112&'DMR 001C NEW'!$A$3:$A$1112),0),MATCH('001-C DMR'!$EY$11,'DMR 001C NEW'!$A$2:$O$2,0)),"")} | FF12: =IF(FH12<FG12,"<","") | FG12: {=_xlfn.IFNA(INDEX('DMR 001C NEW'!$A$3:$O$9999,MATCH(('001-C DMR'!$FF$6&'001-C DMR'!$FF$10&'001-C DMR'!$B12),('DMR 001C NEW'!$E$3:$E$7246&'DMR 001C NEW'!$B$3:$B$7246&'DMR 001C NEW'!$A$3:$A$7246),0),MATCH('001-C DMR'!$FG$11,'DMR 001C NEW'!$A$2:$O$2,0)),"")} -> 0 | FH12: {=_xlfn.IFNA(INDEX('DMR 001C NEW'!$A$3:$O$9999,MATCH(('001-C DMR'!$FF$6&'001-C DMR'!$FF$10&'001-C DMR'!$B12),('DMR 001C NEW'!$E$3:$E$7246&'DMR 001C NEW'!$B$3:$B$7246&'DMR 001C NEW'!$A$3:$A$7246),0),MATCH('001-C DMR'!$FH$11,'DMR 001C NEW'!$A$2:$O$2,0)),"")} -> 4 | FI12: =IF(FK12<FJ12,"<","") | FJ12: {=_xlfn.IFNA(INDEX('DMR 001C NEW'!$A$3:$O$9999,MATCH(('001-C DMR'!$FF$6&'001-C DMR'!$FI$10&'001-C DMR'!$B12),('DMR 001C NEW'!$E$3:$E$7246&'DMR 001C NEW'!$B$3:$B$7246&'DMR 001C NEW'!$A$3:$A$7246),0),MATCH('001-C DMR'!$FG$11,'DMR 001C NEW'!$A$2:$O$2,0)),"")} -> 0 | FK12: {=_xlfn.IFNA(INDEX('DMR 001C NEW'!$A$3:$O$9999,MATCH(('001-C DMR'!$FF$6&'001-C DMR'!$FI$10&'001-C DMR'!$B12),('DMR 001C NEW'!$E$3:$E$7246&'DMR 001C NEW'!$B$3:$B$7246&'DMR 001C NEW'!$A$3:$A$7246),0),MATCH('001-C DMR'!$FH$11,'DMR 001C NEW'!$A$2:$O$2,0)),"")} -> 3 | FL12: {=IFERROR((($FH12*$EI12)+($FK12*$EJ12))/($EK12),"")} -> 3.4343976 | FM12: =IF($A12="Sat",(AVERAGE(FL12)),"") | FN12: =IF($A12="Sat",COUNT(FL5:FL12),"") | FP12: {=_xlfn.IFNA(INDEX('DMR 001C NEW'!$A$3:$O$999,MATCH(('001-C DMR'!$FF$6&'001-C DMR'!FP$10&'001-C DMR'!$B12),('DMR 001C NEW'!$E$3:$E$1112&'DMR 001C NEW'!$B$3:$B$1112&'DMR 001C NEW'!$A$3:$A$1112),0),MATCH('001-C DMR'!$FH$11,'DMR 001C NEW'!$A$2:$O$2,0)),"")} | FQ12: {=_xlfn.IFNA(INDEX('DMR 001C NEW'!$A$3:$O$999,MATCH(('001-C DMR'!$FF$6&'001-C DMR'!FQ$10&'001-C DMR'!$B12),('DMR 001C NEW'!$E$3:$E$1112&'DMR 001C NEW'!$B$3:$B$1112&'DMR 001C NEW'!$A$3:$A$1112),0),MATCH('001-C DMR'!$FH$11,'DMR 001C NEW'!$A$2:$O$2,0)),"")} | FR12: {=_xlfn.IFNA(INDEX('DMR 001C NEW'!$A$3:$O$999,MATCH(('001-C DMR'!$FF$6&'001-C DMR'!FR$10&'001-C DMR'!$B12),('DMR 001C NEW'!$E$3:$E$1112&'DMR 001C NEW'!$B$3:$B$1112&'DMR 001C NEW'!$A$3:$A$1112),0),MATCH('001-C DMR'!$FH$11,'DMR 001C NEW'!$A$2:$O$2,0)),"")} | FS12: {=_xlfn.IFNA(INDEX('DMR 001C NEW'!$A$3:$O$999,MATCH(('001-C DMR'!$FF$6&'001-C DMR'!FS$10&'001-C DMR'!$B12),('DMR 001C NEW'!$E$3:$E$1112&'DMR 001C NEW'!$B$3:$B$1112&'DMR 001C NEW'!$A$3:$A$1112),0),MATCH('001-C DMR'!$FH$11,'DMR 001C NEW'!$A$2:$O$2,0)),"")} | FT12: {=_xlfn.IFNA(INDEX('DMR 001C NEW'!$A$3:$O$999,MATCH(('001-C DMR'!$FF$6&'001-C DMR'!FT$10&'001-C DMR'!$B12),('DMR 001C NEW'!$E$3:$E$1112&'DMR 001C NEW'!$B$3:$B$1112&'DMR 001C NEW'!$A$3:$A$1112),0),MATCH('001-C DMR'!$FH$11,'DMR 001C NEW'!$A$2:$O$2,0)),"")} | FU12: {=_xlfn.IFNA(INDEX('DMR 001C NEW'!$A$3:$O$999,MATCH(('001-C DMR'!$FF$6&'001-C DMR'!FU$10&'001-C DMR'!$B12),('DMR 001C NEW'!$E$3:$E$1112&'DMR 001C NEW'!$B$3:$B$1112&'DMR 001C NEW'!$A$3:$A$1112),0),MATCH('001-C DMR'!$FH$11,'DMR 001C NEW'!$A$2:$O$2,0)),"")} | FW12: =IF(FY12<FX12,"<","") | FX12: {=_xlfn.IFNA(INDEX('DMR 001C NEW'!$A$3:$O$9999,MATCH(('001-C DMR'!$FW$6&'001-C DMR'!$FW$10&'001-C DMR'!$B12),('DMR 001C NEW'!$E$3:$E$7246&'DMR 001C NEW'!$B$3:$B$7246&'DMR 001C NEW'!$A$3:$A$7246),0),MATCH('001-C DMR'!$FX$11,'DMR 001C NEW'!$A$2:$O$2,0)),"")} | FY12: {=_xlfn.IFNA(INDEX('DMR 001C NEW'!$A$3:$O$9999,MATCH(('001-C DMR'!$FW$6&'001-C DMR'!$FW$10&'001-C DMR'!$B12),('DMR 001C NEW'!$E$3:$E$7246&'DMR 001C NEW'!$B$3:$B$7246&'DMR 001C NEW'!$A$3:$A$7246),0),MATCH('001-C DMR'!$FY$11,'DMR 001C NEW'!$A$2:$O$2,0)),"")} | FZ12: =IF(GB12<GA12,"<","") | GA12: {=_xlfn.IFNA(INDEX('DMR 001C NEW'!$A$3:$O$9999,MATCH(('001-C DMR'!$FW$6&'001-C DMR'!$FZ$10&'001-C DMR'!$B12),('DMR 001C NEW'!$E$3:$E$7246&'DMR 001C NEW'!$B$3:$B$7246&'DMR 001C NEW'!$A$3:$A$7246),0),MATCH('001-C DMR'!$FX$11,'DMR 001C NEW'!$A$2:$O$2,0)),"")} | GB12: {=_xlfn.IFNA(INDEX('DMR 001C NEW'!$A$3:$O$9999,MATCH(('001-C DMR'!$FW$6&'001-C DMR'!$FZ$10&'001-C DMR'!$B12),('DMR 001C NEW'!$E$3:$E$7246&'DMR 001C NEW'!$B$3:$B$7246&'DMR 001C NEW'!$A$3:$A$7246),0),MATCH('001-C DMR'!$GB$11,'DMR 001C NEW'!$A$2:$O$2,0)),"")} | GC12: =IFERROR((($FY12*$EI12)+($GB12*$EJ12))/($EK12),"") | GD12: =IF($A12="Sat",COUNT(GB5:GB12),"") | GE12: {=_xlfn.IFNA(INDEX('DMR 001C NEW'!$A$3:$O$999,MATCH(('001-C DMR'!$FW$6&'001-C DMR'!GE$10&'001-C DMR'!$B12),('DMR 001C NEW'!$E$3:$E$1112&'DMR 001C NEW'!$B$3:$B$1112&'DMR 001C NEW'!$A$3:$A$1112),0),MATCH('001-C DMR'!$FY$11,'DMR 001C NEW'!$A$2:$O$2,0)),"")} | GF12: {=_xlfn.IFNA(INDEX('DMR 001C NEW'!$A$3:$O$999,MATCH(('001-C DMR'!$FW$6&'001-C DMR'!GF$10&'001-C DMR'!$B12),('DMR 001C NEW'!$E$3:$E$1112&'DMR 001C NEW'!$B$3:$B$1112&'DMR 001C NEW'!$A$3:$A$1112),0),MATCH('001-C DMR'!$FY$11,'DMR 001C NEW'!$A$2:$O$2,0)),"")} | GG12: {=_xlfn.IFNA(INDEX('DMR 001C NEW'!$A$3:$O$999,MATCH(('001-C DMR'!$FW$6&'001-C DMR'!GG$10&'001-C DMR'!$B12),('DMR 001C NEW'!$E$3:$E$1112&'DMR 001C NEW'!$B$3:$B$1112&'DMR 001C NEW'!$A$3:$A$1112),0),MATCH('001-C DMR'!$FY$11,'DMR 001C NEW'!$A$2:$O$2,0)),"")} | GH12: {=_xlfn.IFNA(INDEX('DMR 001C NEW'!$A$3:$O$999,MATCH(('001-C DMR'!$FW$6&'001-C DMR'!GH$10&'001-C DMR'!$B12),('DMR 001C NEW'!$E$3:$E$1112&'DMR 001C NEW'!$B$3:$B$1112&'DMR 001C NEW'!$A$3:$A$1112),0),MATCH('001-C DMR'!$FY$11,'DMR 001C NEW'!$A$2:$O$2,0)),"")} | GI12: {=_xlfn.IFNA(INDEX('DMR 001C NEW'!$A$3:$O$999,MATCH(('001-C DMR'!$FW$6&'001-C DMR'!GI$10&'001-C DMR'!$B12),('DMR 001C NEW'!$E$3:$E$1112&'DMR 001C NEW'!$B$3:$B$1112&'DMR 001C NEW'!$A$3:$A$1112),0),MATCH('001-C DMR'!$FY$11,'DMR 001C NEW'!$A$2:$O$2,0)),"")} | GJ12: {=_xlfn.IFNA(INDEX('DMR 001C NEW'!$A$3:$O$999,MATCH(('001-C DMR'!$FW$6&'001-C DMR'!GJ$10&'001-C DMR'!$B12),('DMR 001C NEW'!$E$3:$E$1112&'DMR 001C NEW'!$B$3:$B$1112&'DMR 001C NEW'!$A$3:$A$1112),0),MATCH('001-C DMR'!$FY$11,'DMR 001C NEW'!$A$2:$O$2,0)),"")} | GK12: {=_xlfn.IFNA(INDEX('DMR 001C NEW'!$A$3:$O$9999,MATCH(('001-C DMR'!$GK$6&'001-C DMR'!$GK$10&'001-C DMR'!$B12),('DMR 001C NEW'!$E$3:$E$9018&'DMR 001C NEW'!$B$3:$B$9018&'DMR 001C NEW'!$A$3:$A$9018),0),MATCH('001-C DMR'!$GK$11,'DMR 001C NEW'!$A$2:$O$2,0)),"")} -> n | GL12: {=_xlfn.IFNA(INDEX('DMR 001C NEW'!$A$3:$O$9999,MATCH(('001-C DMR'!$GK$6&'001-C DMR'!$GL$10&'001-C DMR'!$B12),('DMR 001C NEW'!$E$3:$E$9018&'DMR 001C NEW'!$B$3:$B$9018&'DMR 001C NEW'!$A$3:$A$9018),0),MATCH('001-C DMR'!$GK$11,'DMR 001C NEW'!$A$2:$O$2,0)),"")} -> n | GN12: =IF($A12="Sat",COUNT(GL5:GL12),"")
