Workbook
Name _4173_1: 'DMR Flows-Effluent'!$A$2:$F$732
Name _4174_1: 'DMR 001C TIN & TP'!$A$2:$M$901
Name drilldown: 'DMR 001C TIN & TP'!$XBA$2:$XBA$901
Name drilldown: 'DMR Flows-Effluent'!$XBA$2:$XBA$732

Sheet Reg 85
A1: Period Start | B1: =EDATE(B3,B4) -> 43344
A2: Period End | B2: =EOMONTH(B3,0) -> 43708
A3: Month | B3: 43678
A4: Months | B4: -11
A6: 001-C | G6: flow | I6: Ammonia Nitrogen, AA | R6: Ammonia Check | X6: NO3+NO2 as N - Cd Red. | AG6: NO5 Check | AM6: TIN | AQ6: Phosphorus, Tot. | BA6: PW Check
I7: 00610 | X7: 00630
A8: Limits | F8: Average | G8: Tag
A9: PQL
A10: Location Code | F10: FI-F350 | G10: FI-F4 | I10: 1002B | M10: 1004B | R10: 6I | S10: 2B | T10: 4B | U10: 6 | V10: 2I | W10: 4I | X10: 1002B | AB10: 1004B | AG10: 6I | AH10: 2B | AI10: 4B | AJ10: 6 | AK10: 2I | AL10: 4I | AM10: 6 | AQ10: 2B | AU10: 4B | BA10: 6I | BB10: 1002B | BC10: 1004B | BD10: 6 | BE10: 2I | BF10: 4I
A11: Day | B11: Date | F11: North | G11: South | H11: Total | I11: ML Comparison | J11: ML | K11: Result | L11: computing result | M11: ML Comparison | N11: ML | O11: Result | P11: computing result | Q11: Flow weighted | R11: Result | X11: ML Comparison | Y11: ML | Z11: Result | AA11: computing result | AB11: ML Comparison | AC11: ML | AD11: Result | AE11: computing result | AF11: Flow weighted | AG11: Result | AM11: ML Comparison | AN11: ML | AO11: Result | AP11: Count | AQ11: ML Comparison | AR11: ML | AS11: Result | AT11: computing result | AU11: ML Comparison | AV11: ML | AW11: Result | AX11: computing result | AY11: Flow weighted | AZ11: Count | BA11: Result
A12: =TEXT(B12,"ddd") -> Sat | B12: =B1 -> 43344 | C12: =EOMONTH(B12,0) -> 43373 | D12: =EOMONTH(B12,-1)+1 -> 43344 | E12: =DAY(EOMONTH(B12,0)) -> 30 | F12: {=_xlfn.IFNA(INDEX('DMR Flows-Effluent'!$A$3:$F$9999,MATCH(($F$10&$B12),('DMR Flows-Effluent'!$B$3:$B$9999&'DMR Flows-Effluent'!$A$3:$A$9999),0),MATCH($F$8,'DMR Flows-Effluent'!$A$2:$F$2,0)),"")} -> 48.9957 | G12: {=_xlfn.IFNA(INDEX('DMR Flows-Effluent'!$A$3:$F$9999,MATCH(($G$10&$B12),('DMR Flows-Effluent'!$B$3:$B$9999&'DMR Flows-Effluent'!$A$3:$A$9999),0),MATCH($F$8,'DMR Flows-Effluent'!$A$2:$F$2,0)),"")} -> 64.9214 | H12: =SUM(F12:G12) -> 113.9171 | I12: =IFERROR(IF(L12<VALUE(J12),"<",""),"") | J12: {=_xlfn.IFNA((INDEX('DMR 001C TIN & TP'!$A$3:$M$10005,MATCH(('Reg 85'!$I$6:$Q$6&'Reg 85'!$I$10:$K$10&'Reg 85'!$B12),('DMR 001C TIN & TP'!$E$3:$E$10005&'DMR 001C TIN & TP'!$B$3:$B$10005&'DMR 001C TIN & TP'!$A$3:$A$10005),0),MATCH('Reg 85'!$J$11,'DMR 001C TIN & TP'!$A$2:$M$2,0))),"")} | K12: {=_xlfn.IFNA((INDEX('DMR 001C TIN & TP'!$A$3:$M$10005,MATCH(('Reg 85'!$I$6:$Q$6&'Reg 85'!$I$10:$K$10&'Reg 85'!$B12),('DMR 001C TIN & TP'!$E$3:$E$10005&'DMR 001C TIN & TP'!$B$3:$B$10005&'DMR 001C TIN & TP'!$A$3:$A$10005),0),MATCH('Reg 85'!$K$11,'DMR 001C TIN & TP'!$A$2:$M$2,0))),"")} | L12: =IFERROR(IF(VALUE(K12)<VALUE(J12),0,VALUE(K12)),"") | M12: =IFERROR(IF(P12<VALUE(N12),"<",""),"") | N12: {=_xlfn.IFNA((INDEX('DMR 001C TIN & TP'!$A$3:$M$10005,MATCH(('Reg 85'!$I$6:$Q$6&'Reg 85'!$M$10&'Reg 85'!$B12),('DMR 001C TIN & TP'!$E$3:$E$10005&'DMR 001C TIN & TP'!$B$3:$B$10005&'DMR 001C TIN & TP'!$A$3:$A$10005),0),MATCH('Reg 85'!$N$11,'DMR 001C TIN & TP'!$A$2:$M$2,0))),"")} | O12: {=_xlfn.IFNA((INDEX('DMR 001C TIN & TP'!$A$3:$M$10005,MATCH(('Reg 85'!$I$6:$Q$6&'Reg 85'!$M$10&'Reg 85'!$B12),('DMR 001C TIN & TP'!$E$3:$E$10005&'DMR 001C TIN & TP'!$B$3:$B$10005&'DMR 001C TIN & TP'!$A$3:$A$10005),0),MATCH('Reg 85'!$O$11,'DMR 001C TIN & TP'!$A$2:$M$2,0))),"")} | P12: =IFERROR(IF(VALUE(O12)<VALUE(N12),0,VALUE(O12)),"") | Q12: {=IFERROR(((L12*$F12)+(P12*$G12))/($H12),"")} | R12: {=_xlfn.IFNA((INDEX('DMR 001C TIN & TP'!$A$3:$M$10005,MATCH(('Reg 85'!$I$6:$Q$6&'Reg 85'!R$10&'Reg 85'!$B12),('DMR 001C TIN & TP'!$E$3:$E$10005&'DMR 001C TIN & TP'!$B$3:$B$10005&'DMR 001C TIN & TP'!$A$3:$A$10005),0),MATCH('Reg 85'!$O$11,'DMR 001C TIN & TP'!$A$2:$M$2,0))),"")} | S12: {=_xlfn.IFNA((INDEX('DMR 001C TIN & TP'!$A$3:$M$10005,MATCH(('Reg 85'!$I$6:$Q$6&'Reg 85'!S$10&'Reg 85'!$B12),('DMR 001C TIN & TP'!$E$3:$E$10005&'DMR 001C TIN & TP'!$B$3:$B$10005&'DMR 001C TIN & TP'!$A$3:$A$10005),0),MATCH('Reg 85'!$O$11,'DMR 001C TIN & TP'!$A$2:$M$2,0))),"")} | T12: {=_xlfn.IFNA((INDEX('DMR 001C TIN & TP'!$A$3:$M$10005,MATCH(('Reg 85'!$I$6:$Q$6&'Reg 85'!T$10&'Reg 85'!$B12),('DMR 001C TIN & TP'!$E$3:$E$10005&'DMR 001C TIN & TP'!$B$3:$B$10005&'DMR 001C TIN & TP'!$A$3:$A$10005),0),MATCH('Reg 85'!$O$11,'DMR 001C TIN & TP'!$A$2:$M$2,0))),"")} | U12: {=_xlfn.IFNA((INDEX('DMR 001C TIN & TP'!$A$3:$M$10005,MATCH(('Reg 85'!$I$6:$Q$6&'Reg 85'!U$10&'Reg 85'!$B12),('DMR 001C TIN & TP'!$E$3:$E$10005&'DMR 001C TIN & TP'!$B$3:$B$10005&'DMR 001C TIN & TP'!$A$3:$A$10005),0),MATCH('Reg 85'!$O$11,'DMR 001C TIN & TP'!$A$2:$M$2,0))),"")} | V12: {=_xlfn.IFNA((INDEX('DMR 001C TIN & TP'!$A$3:$M$10005,MATCH(('Reg 85'!$I$6:$Q$6&'Reg 85'!V$10&'Reg 85'!$B12),('DMR 001C TIN & TP'!$E$3:$E$10005&'DMR 001C TIN & TP'!$B$3:$B$10005&'DMR 001C TIN & TP'!$A$3:$A$10005),0),MATCH('Reg 85'!$O$11,'DMR 001C TIN & TP'!$A$2:$M$2,0))),"")} | W12: {=_xlfn.IFNA((INDEX('DMR 001C TIN & TP'!$A$3:$M$10005,MATCH(('Reg 85'!$I$6:$Q$6&'Reg 85'!W$10&'Reg 85'!$B12),('DMR 001C TIN & TP'!$E$3:$E$10005&'DMR 001C TIN & TP'!$B$3:$B$10005&'DMR 001C TIN & TP'!$A$3:$A$10005),0),MATCH('Reg 85'!$O$11,'DMR 001C TIN & TP'!$A$2:$M$2,0))),"")} | X12: =IFERROR(IF(AA12<VALUE(Y12),"<",""),"") | Y12: {=_xlfn.IFNA((INDEX('DMR 001C TIN & TP'!$A$3:$M$10005,MATCH(('Reg 85'!$X$6&'Reg 85'!$X$10&'Reg 85'!$B12),('DMR 001C TIN & TP'!$E$3:$E$10005&'DMR 001C TIN & TP'!$B$3:$B$10005&'DMR 001C TIN & TP'!$A$3:$A$10005),0),MATCH('Reg 85'!$Y$11,'DMR 001C TIN & TP'!$A$2:$M$2,0))),"")} | Z12: {=_xlfn.IFNA((INDEX('DMR 001C TIN & TP'!$A$3:$M$10005,MATCH(('Reg 85'!$X$6&'Reg 85'!$X$10&'Reg 85'!$B12),('DMR 001C TIN & TP'!$E$3:$E$10005&'DMR 001C TIN & TP'!$B$3:$B$10005&'DMR 001C TIN & TP'!$A$3:$A$10005),0),MATCH('Reg 85'!$Z$11,'DMR 001C TIN & TP'!$A$2:$M$2,0))),"")} | AA12: =IFERROR(IF(VALUE(Z12)<VALUE(Y12),0,VALUE(Z12)),"") | AB12: =IFERROR(IF(AE12<VALUE(AC12),"<",""),"") | AC12: {=_xlfn.IFNA((INDEX('DMR 001C TIN & TP'!$A$3:$M$10005,MATCH(('Reg 85'!$X$6&'Reg 85'!$AB$10&'Reg 85'!$B12),('DMR 001C TIN & TP'!$E$3:$E$10005&'DMR 001C TIN & TP'!$B$3:$B$10005&'DMR 001C TIN & TP'!$A$3:$A$10005),0),MATCH('Reg 85'!$AC$11,'DMR 001C TIN & TP'!$A$2:$M$2,0))),"")} | AD12: {=_xlfn.IFNA((INDEX('DMR 001C TIN & TP'!$A$3:$M$10005,MATCH(('Reg 85'!$X$6&'Reg 85'!$AB$10&'Reg 85'!$B12),('DMR 001C TIN & TP'!$E$3:$E$10005&'DMR 001C TIN & TP'!$B$3:$B$10005&'DMR 001C TIN & TP'!$A$3:$A$10005),0),MATCH('Reg 85'!$AD$11,'DMR 001C TIN & TP'!$A$2:$M$2,0))),"")} | AE12: =IFERROR(IF(VALUE(AD12)<VALUE(AC12),0,VALUE(AD12)),"") | AF12: =IFERROR(((AA12*$F12)+(AE12*$G12))/($H12),"") | AG12: {=_xlfn.IFNA((INDEX('DMR 001C TIN & TP'!$A$3:$M$10005,MATCH(('Reg 85'!$X$6&'Reg 85'!AG$10&'Reg 85'!$B12),('DMR 001C TIN & TP'!$E$3:$E$10005&'DMR 001C TIN & TP'!$B$3:$B$10005&'DMR 001C TIN & TP'!$A$3:$A$10005),0),MATCH('Reg 85'!$AG$11,'DMR 001C TIN & TP'!$A$2:$M$2,0))),"")} | AH12: {=_xlfn.IFNA((INDEX('DMR 001C TIN & TP'!$A$3:$M$10005,MATCH(('Reg 85'!$X$6&'Reg 85'!AH$10&'Reg 85'!$B12),('DMR 001C TIN & TP'!$E$3:$E$10005&'DMR 001C TIN & TP'!$B$3:$B$10005&'DMR 001C TIN & TP'!$A$3:$A$10005),0),MATCH('Reg 85'!$AG$11,'DMR 001C TIN & TP'!$A$2:$M$2,0))),"")} | AI12: {=_xlfn.IFNA((INDEX('DMR 001C TIN & TP'!$A$3:$M$10005,MATCH(('Reg 85'!$X$6&'Reg 85'!AI$10&'Reg 85'!$B12),('DMR 001C TIN & TP'!$E$3:$E$10005&'DMR 001C TIN & TP'!$B$3:$B$10005&'DMR 001C TIN & TP'!$A$3:$A$10005),0),MATCH('Reg 85'!$AG$11,'DMR 001C TIN & TP'!$A$2:$M$2,0))),"")} | AJ12: {=_xlfn.IFNA((INDEX('DMR 001C TIN & TP'!$A$3:$M$10005,MATCH(('Reg 85'!$X$6&'Reg 85'!AJ$10&'Reg 85'!$B12),('DMR 001C TIN & TP'!$E$3:$E$10005&'DMR 001C TIN & TP'!$B$3:$B$10005&'DMR 001C TIN & TP'!$A$3:$A$10005),0),MATCH('Reg 85'!$AG$11,'DMR 001C TIN & TP'!$A$2:$M$2,0))),"")} | AK12: {=_xlfn.IFNA((INDEX('DMR 001C TIN & TP'!$A$3:$M$10005,MATCH(('Reg 85'!$X$6&'Reg 85'!AK$10&'Reg 85'!$B12),('DMR 001C TIN & TP'!$E$3:$E$10005&'DMR 001C TIN & TP'!$B$3:$B$10005&'DMR 001C TIN & TP'!$A$3:$A$10005),0),MATCH('Reg 85'!$AG$11,'DMR 001C TIN & TP'!$A$2:$M$2,0))),"")} | AL12: {=_xlfn.IFNA((INDEX('DMR 001C TIN & TP'!$A$3:$M$10005,MATCH(('Reg 85'!$X$6&'Reg 85'!AL$10&'Reg 85'!$B12),('DMR 001C TIN & TP'!$E$3:$E$10005&'DMR 001C TIN & TP'!$B$3:$B$10005&'DMR 001C TIN & TP'!$A$3:$A$10005),0),MATCH('Reg 85'!$AG$11,'DMR 001C TIN & TP'!$A$2:$M$2,0))),"")} | AO12: =IFERROR(Q12+AF12,"") | AP12: =IF(COUNT(IF((#REF!<=C12)*(#REF!>=D12)*(B12=EOMONTH(B12,0)),#REF!,""))=0,"",COUNT(IF((#REF!<=C12)*(#REF!>=D12)*(B12=EOMONTH(B12,0)),#REF!,""))) | AQ12: =IFERROR(IF(VALUE(AT12)<VALUE(AR12),"<",""),"") | AR12: {=_xlfn.IFNA((INDEX('DMR 001C TIN & TP'!$A$3:$M$10005,MATCH(('Reg 85'!$AQ$6&'Reg 85'!$AQ$10&'Reg 85'!$B12),('DMR 001C TIN & TP'!$E$3:$E$10005&'DMR 001C TIN & TP'!$B$3:$B$10005&'DMR 001C TIN & TP'!$A$3:$A$10005),0),MATCH('Reg 85'!$AR$11,'DMR 001C TIN & TP'!$A$2:$M$2,0))),"")} | AS12: {=_xlfn.IFNA((INDEX('DMR 001C TIN & TP'!$A$3:$M$10005,MATCH(('Reg 85'!$AQ$6&'Reg 85'!$AQ$10&'Reg 85'!$B12),('DMR 001C TIN & TP'!$E$3:$E$10005&'DMR 001C TIN & TP'!$B$3:$B$10005&'DMR 001C TIN & TP'!$A$3:$A$10005),0),MATCH('Reg 85'!$AS$11,'DMR 001C TIN & TP'!$A$2:$M$2,0))),"")} | AT12: =IFERROR(IF(VALUE(AS12)<VALUE(AR12),0,VALUE(AS12)),"") | AV12: {=_xlfn.IFNA((INDEX('DMR 001C TIN & TP'!$A$3:$M$10005,MATCH(('Reg 85'!$AQ$6&'Reg 85'!$AU$10&'Reg 85'!$B12),('DMR 001C TIN & TP'!$E$3:$E$10005&'DMR 001C TIN & TP'!$B$3:$B$10005&'DMR 001C TIN & TP'!$A$3:$A$10005),0),MATCH('Reg 85'!$AV$11,'DMR 001C TIN & TP'!$A$2:$M$2,0))),"")} | AW12: {=_xlfn.IFNA((INDEX('DMR 001C TIN & TP'!$A$3:$M$10005,MATCH(('Reg 85'!$AQ$6&'Reg 85'!$AU$10&'Reg 85'!$B12),('DMR 001C TIN & TP'!$E$3:$E$10005&'DMR 001C TIN & TP'!$B$3:$B$10005&'DMR 001C TIN & TP'!$A$3:$A$10005),0),MATCH('Reg 85'!$AW$11,'DMR 001C TIN & TP'!$A$2:$M$2,0))),"")} | AX12: =IFERROR(IF(VALUE(AW12)<VALUE(AV12),0,VALUE(AW12)),"") | AY12: =IFERROR(((AT12*$F12)+(AX12*$G12))/($H12),"") | AZ12: =IF(COUNT(IF((#REF!<=C12)*(#REF!>=D12)*(B12=EOMONTH(B12,0)),#REF!,""))=0,"",COUNT(IF((#REF!<=C12)*(#REF!>=D12)*(B12=EOMONTH(B12,0)),#REF!,""))) | BA12: {=_xlfn.IFNA((INDEX('DMR 001C TIN & TP'!$A$3:$M$10005,MATCH(('Reg 85'!$AQ$6&'Reg 85'!BA$10&'Reg 85'!$B12),('DMR 001C TIN & TP'!$E$3:$E$10005&'DMR 001C TIN & TP'!$B$3:$B$10005&'DMR 001C TIN & TP'!$A$3:$A$10005),0),MATCH('Reg 85'!$AG$11,'DMR 001C TIN & TP'!$A$2:$M$2,0))),"")} | BB12: {=_xlfn.IFNA((INDEX('DMR 001C TIN & TP'!$A$3:$M$10005,MATCH(('Reg 85'!$AQ$6&'Reg 85'!BB$10&'Reg 85'!$B12),('DMR 001C TIN & TP'!$E$3:$E$10005&'DMR 001C TIN & TP'!$B$3:$B$10005&'DMR 001C TIN & TP'!$A$3:$A$10005),0),MATCH('Reg 85'!$AG$11,'DMR 001C TIN & TP'!$A$2:$M$2,0))),"")} | BC12: {=_xlfn.IFNA((INDEX('DMR 001C TIN & TP'!$A$3:$M$10005,MATCH(('Reg 85'!$AQ$6&'Reg 85'!BC$10&'Reg 85'!$B12),('DMR 001C TIN & TP'!$E$3:$E$10005&'DMR 001C TIN & TP'!$B$3:$B$10005&'DMR 001C TIN & TP'!$A$3:$A$10005),0),MATCH('Reg 85'!$AG$11,'DMR 001C TIN & TP'!$A$2:$M$2,0))),"")} | BD12: {=_xlfn.IFNA((INDEX('DMR 001C TIN & TP'!$A$3:$M$10005,MATCH(('Reg 85'!$AQ$6&'Reg 85'!BD$10&'Reg 85'!$B12),('DMR 001C TIN & TP'!$E$3:$E$10005&'DMR 001C TIN & TP'!$B$3:$B$10005&'DMR 001C TIN & TP'!$A$3:$A$10005),0),MATCH('Reg 85'!$AG$11,'DMR 001C TIN & TP'!$A$2:$M$2,0))),"")} | BE12: {=_xlfn.IFNA((INDEX('DMR 001C TIN & TP'!$A$3:$M$10005,MATCH(('Reg 85'!$AQ$6&'Reg 85'!BE$10&'Reg 85'!$B12),('DMR 001C TIN & TP'!$E$3:$E$10005&'DMR 001C TIN & TP'!$B$3:$B$10005&'DMR 001C TIN & TP'!$A$3:$A$10005),0),MATCH('Reg 85'!$AG$11,'DMR 001C TIN & TP'!$A$2:$M$2,0))),"")} | BF12: {=_xlfn.IFNA((INDEX('DMR 001C TIN & TP'!$A$3:$M$10005,MATCH(('Reg 85'!$AQ$6&'Reg 85'!BF$10&'Reg 85'!$B12),('DMR 001C TIN & TP'!$E$3:$E$10005&'DMR 001C TIN & TP'!$B$3:$B$10005&'DMR 001C TIN & TP'!$A$3:$A$10005),0),MATCH('Reg 85'!$AG$11,'DMR 001C TIN & TP'!$A$2:$M$2,0))),"")}
A13: =TEXT(B13,"ddd") -> Sun | B13: =B12+1 -> 43345 | C13: =EOMONTH(B13,0) -> 43373 | D13: =EOMONTH(B13,-1)+1 -> 43344 | E13: =DAY(EOMONTH(B13,0)) -> 30 | F13: {=_xlfn.IFNA(INDEX('DMR Flows-Effluent'!$A$3:$F$9999,MATCH(($F$10&$B13),('DMR Flows-Effluent'!$B$3:$B$9999&'DMR Flows-Effluent'!$A$3:$A$9999),0),MATCH($F$8,'DMR Flows-Effluent'!$A$2:$F$2,0)),"")} -> 48.7264 | G13: {=_xlfn.IFNA(INDEX('DMR Flows-Effluent'!$A$3:$F$9999,MATCH(($G$10&$B13),('DMR Flows-Effluent'!$B$3:$B$9999&'DMR Flows-Effluent'!$A$3:$A$9999),0),MATCH($F$8,'DMR Flows-Effluent'!$A$2:$F$2,0)),"")} -> 62.2851 | H13: =SUM(F13:G13) -> 111.0115 | I13: =IFERROR(IF(L13<VALUE(J13),"<",""),"") | J13: {=_xlfn.IFNA((INDEX('DMR 001C TIN & TP'!$A$3:$M$10005,MATCH(('Reg 85'!$I$6:$Q$6&'Reg 85'!$I$10:$K$10&'Reg 85'!$B13),('DMR 001C TIN & TP'!$E$3:$E$10005&'DMR 001C TIN & TP'!$B$3:$B$10005&'DMR 001C TIN & TP'!$A$3:$A$10005),0),MATCH('Reg 85'!$J$11,'DMR 001C TIN & TP'!$A$2:$M$2,0))),"")} | K13: {=_xlfn.IFNA((INDEX('DMR 001C TIN & TP'!$A$3:$M$10005,MATCH(('Reg 85'!$I$6:$Q$6&'Reg 85'!$I$10:$K$10&'Reg 85'!$B13),('DMR 001C TIN & TP'!$E$3:$E$10005&'DMR 001C TIN & TP'!$B$3:$B$10005&'DMR 001C TIN & TP'!$A$3:$A$10005),0),MATCH('Reg 85'!$K$11,'DMR 001C TIN & TP'!$A$2:$M$2,0))),"")} | L13: =IFERROR(IF(VALUE(K13)<VALUE(J13),0,VALUE(K13)),"") | M13: =IFERROR(IF(P13<VALUE(N13),"<",""),"") | N13: {=_xlfn.IFNA((INDEX('DMR 001C TIN & TP'!$A$3:$M$10005,MATCH(('Reg 85'!$I$6:$Q$6&'Reg 85'!$M$10&'Reg 85'!$B13),('DMR 001C TIN & TP'!$E$3:$E$10005&'DMR 001C TIN & TP'!$B$3:$B$10005&'DMR 001C TIN & TP'!$A$3:$A$10005),0),MATCH('Reg 85'!$N$11,'DMR 001C TIN & TP'!$A$2:$M$2,0))),"")} | O13: {=_xlfn.IFNA((INDEX('DMR 001C TIN & TP'!$A$3:$M$10005,MATCH(('Reg 85'!$I$6:$Q$6&'Reg 85'!$M$10&'Reg 85'!$B13),('DMR 001C TIN & TP'!$E$3:$E$10005&'DMR 001C TIN & TP'!$B$3:$B$10005&'DMR 001C TIN & TP'!$A$3:$A$10005),0),MATCH('Reg 85'!$O$11,'DMR 001C TIN & TP'!$A$2:$M$2,0))),"")} | P13: =IFERROR(IF(VALUE(O13)<VALUE(N13),0,VALUE(O13)),"") | Q13: {=IFERROR(((L13*$F13)+(P13*$G13))/($H13),"")} | R13: {=_xlfn.IFNA((INDEX('DMR 001C TIN & TP'!$A$3:$M$10005,MATCH(('Reg 85'!$I$6:$Q$6&'Reg 85'!R$10&'Reg 85'!$B13),('DMR 001C TIN & TP'!$E$3:$E$10005&'DMR 001C TIN & TP'!$B$3:$B$10005&'DMR 001C TIN & TP'!$A$3:$A$10005),0),MATCH('Reg 85'!$O$11,'DMR 001C TIN & TP'!$A$2:$M$2,0))),"")} | S13: {=_xlfn.IFNA((INDEX('DMR 001C TIN & TP'!$A$3:$M$10005,MATCH(('Reg 85'!$I$6:$Q$6&'Reg 85'!S$10&'Reg 85'!$B13),('DMR 001C TIN & TP'!$E$3:$E$10005&'DMR 001C TIN & TP'!$B$3:$B$10005&'DMR 001C TIN & TP'!$A$3:$A$10005),0),MATCH('Reg 85'!$O$11,'DMR 001C TIN & TP'!$A$2:$M$2,0))),"")} | T13: {=_xlfn.IFNA((INDEX('DMR 001C TIN & TP'!$A$3:$M$10005,MATCH(('Reg 85'!$I$6:$Q$6&'Reg 85'!T$10&'Reg 85'!$B13),('DMR 001C TIN & TP'!$E$3:$E$10005&'DMR 001C TIN & TP'!$B$3:$B$10005&'DMR 001C TIN & TP'!$A$3:$A$10005),0),MATCH('Reg 85'!$O$11,'DMR 001C TIN & TP'!$A$2:$M$2,0))),"")} | U13: {=_xlfn.IFNA((INDEX('DMR 001C TIN & TP'!$A$3:$M$10005,MATCH(('Reg 85'!$I$6:$Q$6&'Reg 85'!U$10&'Reg 85'!$B13),('DMR 001C TIN & TP'!$E$3:$E$10005&'DMR 001C TIN & TP'!$B$3:$B$10005&'DMR 001C TIN & TP'!$A$3:$A$10005),0),MATCH('Reg 85'!$O$11,'DMR 001C TIN & TP'!$A$2:$M$2,0))),"")} | V13: {=_xlfn.IFNA((INDEX('DMR 001C TIN & TP'!$A$3:$M$10005,MATCH(('Reg 85'!$I$6:$Q$6&'Reg 85'!V$10&'Reg 85'!$B13),('DMR 001C TIN & TP'!$E$3:$E$10005&'DMR 001C TIN & TP'!$B$3:$B$10005&'DMR 001C TIN & TP'!$A$3:$A$10005),0),MATCH('Reg 85'!$O$11,'DMR 001C TIN & TP'!$A$2:$M$2,0))),"")} | W13: {=_xlfn.IFNA((INDEX('DMR 001C TIN & TP'!$A$3:$M$10005,MATCH(('Reg 85'!$I$6:$Q$6&'Reg 85'!W$10&'Reg 85'!$B13),('DMR 001C TIN & TP'!$E$3:$E$10005&'DMR 001C TIN & TP'!$B$3:$B$10005&'DMR 001C TIN & TP'!$A$3:$A$10005),0),MATCH('Reg 85'!$O$11,'DMR 001C TIN & TP'!$A$2:$M$2,0))),"")} | X13: =IFERROR(IF(AA13<VALUE(Y13),"<",""),"") | Y13: {=_xlfn.IFNA((INDEX('DMR 001C TIN & TP'!$A$3:$M$10005,MATCH(('Reg 85'!$X$6&'Reg 85'!$X$10&'Reg 85'!$B13),('DMR 001C TIN & TP'!$E$3:$E$10005&'DMR 001C TIN & TP'!$B$3:$B$10005&'DMR 001C TIN & TP'!$A$3:$A$10005),0),MATCH('Reg 85'!$Y$11,'DMR 001C TIN & TP'!$A$2:$M$2,0))),"")} | Z13: {=_xlfn.IFNA((INDEX('DMR 001C TIN & TP'!$A$3:$M$10005,MATCH(('Reg 85'!$X$6&'Reg 85'!$X$10&'Reg 85'!$B13),('DMR 001C TIN & TP'!$E$3:$E$10005&'DMR 001C TIN & TP'!$B$3:$B$10005&'DMR 001C TIN & TP'!$A$3:$A$10005),0),MATCH('Reg 85'!$Z$11,'DMR 001C TIN & TP'!$A$2:$M$2,0))),"")} | AA13: =IFERROR(IF(VALUE(Z13)<VALUE(Y13),0,VALUE(Z13)),"") | AB13: =IFERROR(IF(AE13<VALUE(AC13),"<",""),"") | AC13: {=_xlfn.IFNA((INDEX('DMR 001C TIN & TP'!$A$3:$M$10005,MATCH(('Reg 85'!$X$6&'Reg 85'!$AB$10&'Reg 85'!$B13),('DMR 001C TIN & TP'!$E$3:$E$10005&'DMR 001C TIN & TP'!$B$3:$B$10005&'DMR 001C TIN & TP'!$A$3:$A$10005),0),MATCH('Reg 85'!$AC$11,'DMR 001C TIN & TP'!$A$2:$M$2,0))),"")} | AD13: {=_xlfn.IFNA((INDEX('DMR 001C TIN & TP'!$A$3:$M$10005,MATCH(('Reg 85'!$X$6&'Reg 85'!$AB$10&'Reg 85'!$B13),('DMR 001C TIN & TP'!$E$3:$E$10005&'DMR 001C TIN & TP'!$B$3:$B$10005&'DMR 001C TIN & TP'!$A$3:$A$10005),0),MATCH('Reg 85'!$AD$11,'DMR 001C TIN & TP'!$A$2:$M$2,0))),"")} | AE13: =IFERROR(IF(VALUE(AD13)<VALUE(AC13),0,VALUE(AD13)),"") | AF13: =IFERROR(((AA13*$F13)+(AE13*$G13))/($H13),"") | AG13: {=_xlfn.IFNA((INDEX('DMR 001C TIN & TP'!$A$3:$M$10005,MATCH(('Reg 85'!$X$6&'Reg 85'!AG$10&'Reg 85'!$B13),('DMR 001C TIN & TP'!$E$3:$E$10005&'DMR 001C TIN & TP'!$B$3:$B$10005&'DMR 001C TIN & TP'!$A$3:$A$10005),0),MATCH('Reg 85'!$AG$11,'DMR 001C TIN & TP'!$A$2:$M$2,0))),"")} | AH13: {=_xlfn.IFNA((INDEX('DMR 001C TIN & TP'!$A$3:$M$10005,MATCH(('Reg 85'!$X$6&'Reg 85'!AH$10&'Reg 85'!$B13),('DMR 001C TIN & TP'!$E$3:$E$10005&'DMR 001C TIN & TP'!$B$3:$B$10005&'DMR 001C TIN & TP'!$A$3:$A$10005),0),MATCH('Reg 85'!$AG$11,'DMR 001C TIN & TP'!$A$2:$M$2,0))),"")} | AI13: {=_xlfn.IFNA((INDEX('DMR 001C TIN & TP'!$A$3:$M$10005,MATCH(('Reg 85'!$X$6&'Reg 85'!AI$10&'Reg 85'!$B13),('DMR 001C TIN & TP'!$E$3:$E$10005&'DMR 001C TIN & TP'!$B$3:$B$10005&'DMR 001C TIN & TP'!$A$3:$A$10005),0),MATCH('Reg 85'!$AG$11,'DMR 001C TIN & TP'!$A$2:$M$2,0))),"")} | AJ13: {=_xlfn.IFNA((INDEX('DMR 001C TIN & TP'!$A$3:$M$10005,MATCH(('Reg 85'!$X$6&'Reg 85'!AJ$10&'Reg 85'!$B13),('DMR 001C TIN & TP'!$E$3:$E$10005&'DMR 001C TIN & TP'!$B$3:$B$10005&'DMR 001C TIN & TP'!$A$3:$A$10005),0),MATCH('Reg 85'!$AG$11,'DMR 001C TIN & TP'!$A$2:$M$2,0))),"")} | AK13: {=_xlfn.IFNA((INDEX('DMR 001C TIN & TP'!$A$3:$M$10005,MATCH(('Reg 85'!$X$6&'Reg 85'!AK$10&'Reg 85'!$B13),('DMR 001C TIN & TP'!$E$3:$E$10005&'DMR 001C TIN & TP'!$B$3:$B$10005&'DMR 001C TIN & TP'!$A$3:$A$10005),0),MATCH('Reg 85'!$AG$11,'DMR 001C TIN & TP'!$A$2:$M$2,0))),"")} | AL13: {=_xlfn.IFNA((INDEX('DMR 001C TIN & TP'!$A$3:$M$10005,MATCH(('Reg 85'!$X$6&'Reg 85'!AL$10&'Reg 85'!$B13),('DMR 001C TIN & TP'!$E$3:$E$10005&'DMR 001C TIN & TP'!$B$3:$B$10005&'DMR 001C TIN & TP'!$A$3:$A$10005),0),MATCH('Reg 85'!$AG$11,'DMR 001C TIN & TP'!$A$2:$M$2,0))),"")} | AO13: =IFERROR(Q13+AF13,"") | AP13: =IF(COUNT(IF((#REF!<=C13)*(#REF!>=D13)*(B13=EOMONTH(B13,0)),#REF!,""))=0,"",COUNT(IF((#REF!<=C13)*(#REF!>=D13)*(B13=EOMONTH(B13,0)),#REF!,""))) | AR13: {=_xlfn.IFNA((INDEX('DMR 001C TIN & TP'!$A$3:$M$10005,MATCH(('Reg 85'!$AQ$6&'Reg 85'!$AQ$10&'Reg 85'!$B13),('DMR 001C TIN & TP'!$E$3:$E$10005&'DMR 001C TIN & TP'!$B$3:$B$10005&'DMR 001C TIN & TP'!$A$3:$A$10005),0),MATCH('Reg 85'!$AR$11,'DMR 001C TIN & TP'!$A$2:$M$2,0))),"")} -> 0.03 | AS13: {=_xlfn.IFNA((INDEX('DMR 001C TIN & TP'!$A$3:$M$10005,MATCH(('Reg 85'!$AQ$6&'Reg 85'!$AQ$10&'Reg 85'!$B13),('DMR 001C TIN & TP'!$E$3:$E$10005&'DMR 001C TIN & TP'!$B$3:$B$10005&'DMR 001C TIN & TP'!$A$3:$A$10005),0),MATCH('Reg 85'!$AS$11,'DMR 001C TIN & TP'!$A$2:$M$2,0))),"")} -> 0.55 | AT13: =IFERROR(IF(VALUE(AS13)<VALUE(AR13),0,VALUE(AS13)),"") -> 0.55 | AV13: {=_xlfn.IFNA((INDEX('DMR 001C TIN & TP'!$A$3:$M$10005,MATCH(('Reg 85'!$AQ$6&'Reg 85'!$AU$10&'Reg 85'!$B13),('DMR 001C TIN & TP'!$E$3:$E$10005&'DMR 001C TIN & TP'!$B$3:$B$10005&'DMR 001C TIN & TP'!$A$3:$A$10005),0),MATCH('Reg 85'!$AV$11,'DMR 001C TIN & TP'!$A$2:$M$2,0))),"")} -> 0.03 | AW13: {=_xlfn.IFNA((INDEX('DMR 001C TIN & TP'!$A$3:$M$10005,MATCH(('Reg 85'!$AQ$6&'Reg 85'!$AU$10&'Reg 85'!$B13),('DMR 001C TIN & TP'!$E$3:$E$10005&'DMR 001C TIN & TP'!$B$3:$B$10005&'DMR 001C TIN & TP'!$A$3:$A$10005),0),MATCH('Reg 85'!$AW$11,'DMR 001C TIN & TP'!$A$2:$M$2,0))),"")} -> 3.6 | AX13: =IFERROR(IF(VALUE(AW13)<VALUE(AV13),0,VALUE(AW13)),"") -> 3.6 | AY13: =IFERROR(((AT13*$F13)+(AX13*$G13))/($H13),"") -> 2.2612601 | AZ13: =IF(COUNT(IF((#REF!<=C13)*(#REF!>=D13)*(B13=EOMONTH(B13,0)),#REF!,""))=0,"",COUNT(IF((#REF!<=C13)*(#REF!>=D13)*(B13=EOMONTH(B13,0)),#REF!,""))) | BA13: {=_xlfn.IFNA((INDEX('DMR 001C TIN & TP'!$A$3:$M$10005,MATCH(('Reg 85'!$AQ$6&'Reg 85'!BA$10&'Reg 85'!$B13),('DMR 001C TIN & TP'!$E$3:$E$10005&'DMR 001C TIN & TP'!$B$3:$B$10005&'DMR 001C TIN & TP'!$A$3:$A$10005),0),MATCH('Reg 85'!$AG$11,'DMR 001C TIN & TP'!$A$2:$M$2,0))),"")} | BB13: {=_xlfn.IFNA((INDEX('DMR 001C TIN & TP'!$A$3:$M$10005,MATCH(('Reg 85'!$AQ$6&'Reg 85'!BB$10&'Reg 85'!$B13),('DMR 001C TIN & TP'!$E$3:$E$10005&'DMR 001C TIN & TP'!$B$3:$B$10005&'DMR 001C TIN & TP'!$A$3:$A$10005),0),MATCH('Reg 85'!$AG$11,'DMR 001C TIN & TP'!$A$2:$M$2,0))),"")} | BC13: {=_xlfn.IFNA((INDEX('DMR 001C TIN & TP'!$A$3:$M$10005,MATCH(('Reg 85'!$AQ$6&'Reg 85'!BC$10&'Reg 85'!$B13),('DMR 001C TIN & TP'!$E$3:$E$10005&'DMR 001C TIN & TP'!$B$3:$B$10005&'DMR 001C TIN & TP'!$A$3:$A$10005),0),MATCH('Reg 85'!$AG$11,'DMR 001C TIN & TP'!$A$2:$M$2,0))),"")} | BD13: {=_xlfn.IFNA((INDEX('DMR 001C TIN & TP'!$A$3:$M$10005,MATCH(('Reg 85'!$AQ$6&'Reg 85'!BD$10&'Reg 85'!$B13),('DMR 001C TIN & TP'!$E$3:$E$10005&'DMR 001C TIN & TP'!$B$3:$B$10005&'DMR 001C TIN & TP'!$A$3:$A$10005),0),MATCH('Reg 85'!$AG$11,'DMR 001C TIN & TP'!$A$2:$M$2,0))),"")} | BE13: {=_xlfn.IFNA((INDEX('DMR 001C TIN & TP'!$A$3:$M$10005,MATCH(('Reg 85'!$AQ$6&'Reg 85'!BE$10&'Reg 85'!$B13),('DMR 001C TIN & TP'!$E$3:$E$10005&'DMR 001C TIN & TP'!$B$3:$B$10005&'DMR 001C TIN & TP'!$A$3:$A$10005),0),MATCH('Reg 85'!$AG$11,'DMR 001C TIN & TP'!$A$2:$M$2,0))),"")} | BF13: {=_xlfn.IFNA((INDEX('DMR 001C TIN & TP'!$A$3:$M$10005,MATCH(('Reg 85'!$AQ$6&'Reg 85'!BF$10&'Reg 85'!$B13),('DMR 001C TIN & TP'!$E$3:$E$10005&'DMR 001C TIN & TP'!$B$3:$B$10005&'DMR 001C TIN & TP'!$A$3:$A$10005),0),MATCH('Reg 85'!$AG$11,'DMR 001C TIN & TP'!$A$2:$M$2,0))),"")}
A14: =TEXT(B14,"ddd") -> Mon | B14: =B13+1 -> 43346 | C14: =EOMONTH(B14,0) -> 43373 | D14: =EOMONTH(B14,-1)+1 -> 43344 | E14: =DAY(EOMONTH(B14,0)) -> 30 | F14: {=_xlfn.IFNA(INDEX('DMR Flows-Effluent'!$A$3:$F$9999,MATCH(($F$10&$B14),('DMR Flows-Effluent'!$B$3:$B$9999&'DMR Flows-Effluent'!$A$3:$A$9999),0),MATCH($F$8,'DMR Flows-Effluent'!$A$2:$F$2,0)),"")} -> 51.5003 | G14: {=_xlfn.IFNA(INDEX('DMR Flows-Effluent'!$A$3:$F$9999,MATCH(($G$10&$B14),('DMR Flows-Effluent'!$B$3:$B$9999&'DMR Flows-Effluent'!$A$3:$A$9999),0),MATCH($F$8,'DMR Flows-Effluent'!$A$2:$F$2,0)),"")} -> 60.1241 | H14: =SUM(F14:G14) -> 111.6244 | I14: =IFERROR(IF(L14<VALUE(J14),"<",""),"") | J14: {=_xlfn.IFNA((INDEX('DMR 001C TIN & TP'!$A$3:$M$10005,MATCH(('Reg 85'!$I$6:$Q$6&'Reg 85'!$I$10:$K$10&'Reg 85'!$B14),('DMR 001C TIN & TP'!$E$3:$E$10005&'DMR 001C TIN & TP'!$B$3:$B$10005&'DMR 001C TIN & TP'!$A$3:$A$10005),0),MATCH('Reg 85'!$J$11,'DMR 001C TIN & TP'!$A$2:$M$2,0))),"")} -> 0.15 | K14: {=_xlfn.IFNA((INDEX('DMR 001C TIN & TP'!$A$3:$M$10005,MATCH(('Reg 85'!$I$6:$Q$6&'Reg 85'!$I$10:$K$10&'Reg 85'!$B14),('DMR 001C TIN & TP'!$E$3:$E$10005&'DMR 001C TIN & TP'!$B$3:$B$10005&'DMR 001C TIN & TP'!$A$3:$A$10005),0),MATCH('Reg 85'!$K$11,'DMR 001C TIN & TP'!$A$2:$M$2,0))),"")} -> 1.18 | L14: =IFERROR(IF(VALUE(K14)<VALUE(J14),0,VALUE(K14)),"") -> 1.18 | M14: =IFERROR(IF(P14<VALUE(N14),"<",""),"") | N14: {=_xlfn.IFNA((INDEX('DMR 001C TIN & TP'!$A$3:$M$10005,MATCH(('Reg 85'!$I$6:$Q$6&'Reg 85'!$M$10&'Reg 85'!$B14),('DMR 001C TIN & TP'!$E$3:$E$10005&'DMR 001C TIN & TP'!$B$3:$B$10005&'DMR 001C TIN & TP'!$A$3:$A$10005),0),MATCH('Reg 85'!$N$11,'DMR 001C TIN & TP'!$A$2:$M$2,0))),"")} -> 0.15 | O14: {=_xlfn.IFNA((INDEX('DMR 001C TIN & TP'!$A$3:$M$10005,MATCH(('Reg 85'!$I$6:$Q$6&'Reg 85'!$M$10&'Reg 85'!$B14),('DMR 001C TIN & TP'!$E$3:$E$10005&'DMR 001C TIN & TP'!$B$3:$B$10005&'DMR 001C TIN & TP'!$A$3:$A$10005),0),MATCH('Reg 85'!$O$11,'DMR 001C TIN & TP'!$A$2:$M$2,0))),"")} -> 0.2 | P14: =IFERROR(IF(VALUE(O14)<VALUE(N14),0,VALUE(O14)),"") -> 0.2 | Q14: {=IFERROR(((L14*$F14)+(P14*$G14))/($H14),"")} -> 0.65214392 | R14: {=_xlfn.IFNA((INDEX('DMR 001C TIN & TP'!$A$3:$M$10005,MATCH(('Reg 85'!$I$6:$Q$6&'Reg 85'!R$10&'Reg 85'!$B14),('DMR 001C TIN & TP'!$E$3:$E$10005&'DMR 001C TIN & TP'!$B$3:$B$10005&'DMR 001C TIN & TP'!$A$3:$A$10005),0),MATCH('Reg 85'!$O$11,'DMR 001C TIN & TP'!$A$2:$M$2,0))),"")} | S14: {=_xlfn.IFNA((INDEX('DMR 001C TIN & TP'!$A$3:$M$10005,MATCH(('Reg 85'!$I$6:$Q$6&'Reg 85'!S$10&'Reg 85'!$B14),('DMR 001C TIN & TP'!$E$3:$E$10005&'DMR 001C TIN & TP'!$B$3:$B$10005&'DMR 001C TIN & TP'!$A$3:$A$10005),0),MATCH('Reg 85'!$O$11,'DMR 001C TIN & TP'!$A$2:$M$2,0))),"")} | T14: {=_xlfn.IFNA((INDEX('DMR 001C TIN & TP'!$A$3:$M$10005,MATCH(('Reg 85'!$I$6:$Q$6&'Reg 85'!T$10&'Reg 85'!$B14),('DMR 001C TIN & TP'!$E$3:$E$10005&'DMR 001C TIN & TP'!$B$3:$B$10005&'DMR 001C TIN & TP'!$A$3:$A$10005),0),MATCH('Reg 85'!$O$11,'DMR 001C TIN & TP'!$A$2:$M$2,0))),"")} | U14: {=_xlfn.IFNA((INDEX('DMR 001C TIN & TP'!$A$3:$M$10005,MATCH(('Reg 85'!$I$6:$Q$6&'Reg 85'!U$10&'Reg 85'!$B14),('DMR 001C TIN & TP'!$E$3:$E$10005&'DMR 001C TIN & TP'!$B$3:$B$10005&'DMR 001C TIN & TP'!$A$3:$A$10005),0),MATCH('Reg 85'!$O$11,'DMR 001C TIN & TP'!$A$2:$M$2,0))),"")} | V14: {=_xlfn.IFNA((INDEX('DMR 001C TIN & TP'!$A$3:$M$10005,MATCH(('Reg 85'!$I$6:$Q$6&'Reg 85'!V$10&'Reg 85'!$B14),('DMR 001C TIN & TP'!$E$3:$E$10005&'DMR 001C TIN & TP'!$B$3:$B$10005&'DMR 001C TIN & TP'!$A$3:$A$10005),0),MATCH('Reg 85'!$O$11,'DMR 001C TIN & TP'!$A$2:$M$2,0))),"")} | W14: {=_xlfn.IFNA((INDEX('DMR 001C TIN & TP'!$A$3:$M$10005,MATCH(('Reg 85'!$I$6:$Q$6&'Reg 85'!W$10&'Reg 85'!$B14),('DMR 001C TIN & TP'!$E$3:$E$10005&'DMR 001C TIN & TP'!$B$3:$B$10005&'DMR 001C TIN & TP'!$A$3:$A$10005),0),MATCH('Reg 85'!$O$11,'DMR 001C TIN & TP'!$A$2:$M$2,0))),"")} | X14: =IFERROR(IF(AA14<VALUE(Y14),"<",""),"") | Y14: {=_xlfn.IFNA((INDEX('DMR 001C TIN & TP'!$A$3:$M$10005,MATCH(('Reg 85'!$X$6&'Reg 85'!$X$10&'Reg 85'!$B14),('DMR 001C TIN & TP'!$E$3:$E$10005&'DMR 001C TIN & TP'!$B$3:$B$10005&'DMR 001C TIN & TP'!$A$3:$A$10005),0),MATCH('Reg 85'!$Y$11,'DMR 001C TIN & TP'!$A$2:$M$2,0))),"")} -> 0.06 | Z14: {=_xlfn.IFNA((INDEX('DMR 001C TIN & TP'!$A$3:$M$10005,MATCH(('Reg 85'!$X$6&'Reg 85'!$X$10&'Reg 85'!$B14),('DMR 001C TIN & TP'!$E$3:$E$10005&'DMR 001C TIN & TP'!$B$3:$B$10005&'DMR 001C TIN & TP'!$A$3:$A$10005),0),MATCH('Reg 85'!$Z$11,'DMR 001C TIN & TP'!$A$2:$M$2,0))),"")} -> 5.57 | AA14: =IFERROR(IF(VALUE(Z14)<VALUE(Y14),0,VALUE(Z14)),"") -> 5.57 | AB14: =IFERROR(IF(AE14<VALUE(AC14),"<",""),"") | AC14: {=_xlfn.IFNA((INDEX('DMR 001C TIN & TP'!$A$3:$M$10005,MATCH(('Reg 85'!$X$6&'Reg 85'!$AB$10&'Reg 85'!$B14),('DMR 001C TIN & TP'!$E$3:$E$10005&'DMR 001C TIN & TP'!$B$3:$B$10005&'DMR 001C TIN & TP'!$A$3:$A$10005),0),MATCH('Reg 85'!$AC$11,'DMR 001C TIN & TP'!$A$2:$M$2,0))),"")} -> 0.06 | AD14: {=_xlfn.IFNA((INDEX('DMR 001C TIN & TP'!$A$3:$M$10005,MATCH(('Reg 85'!$X$6&'Reg 85'!$AB$10&'Reg 85'!$B14),('DMR 001C TIN & TP'!$E$3:$E$10005&'DMR 001C TIN & TP'!$B$3:$B$10005&'DMR 001C TIN & TP'!$A$3:$A$10005),0),MATCH('Reg 85'!$AD$11,'DMR 001C TIN & TP'!$A$2:$M$2,0))),"")} -> 6.12 | AE14: =IFERROR(IF(VALUE(AD14)<VALUE(AC14),0,VALUE(AD14)),"") -> 6.12 | AF14: =IFERROR(((AA14*$F14)+(AE14*$G14))/($H14),"") -> 5.8662458 | AG14: {=_xlfn.IFNA((INDEX('DMR 001C TIN & TP'!$A$3:$M$10005,MATCH(('Reg 85'!$X$6&'Reg 85'!AG$10&'Reg 85'!$B14),('DMR 001C TIN & TP'!$E$3:$E$10005&'DMR 001C TIN & TP'!$B$3:$B$10005&'DMR 001C TIN & TP'!$A$3:$A$10005),0),MATCH('Reg 85'!$AG$11,'DMR 001C TIN & TP'!$A$2:$M$2,0))),"")} | AH14: {=_xlfn.IFNA((INDEX('DMR 001C TIN & TP'!$A$3:$M$10005,MATCH(('Reg 85'!$X$6&'Reg 85'!AH$10&'Reg 85'!$B14),('DMR 001C TIN & TP'!$E$3:$E$10005&'DMR 001C TIN & TP'!$B$3:$B$10005&'DMR 001C TIN & TP'!$A$3:$A$10005),0),MATCH('Reg 85'!$AG$11,'DMR 001C TIN & TP'!$A$2:$M$2,0))),"")} | AI14: {=_xlfn.IFNA((INDEX('DMR 001C TIN & TP'!$A$3:$M$10005,MATCH(('Reg 85'!$X$6&'Reg 85'!AI$10&'Reg 85'!$B14),('DMR 001C TIN & TP'!$E$3:$E$10005&'DMR 001C TIN & TP'!$B$3:$B$10005&'DMR 001C TIN & TP'!$A$3:$A$10005),0),MATCH('Reg 85'!$AG$11,'DMR 001C TIN & TP'!$A$2:$M$2,0))),"")} | AJ14: {=_xlfn.IFNA((INDEX('DMR 001C TIN & TP'!$A$3:$M$10005,MATCH(('Reg 85'!$X$6&'Reg 85'!AJ$10&'Reg 85'!$B14),('DMR 001C TIN & TP'!$E$3:$E$10005&'DMR 001C TIN & TP'!$B$3:$B$10005&'DMR 001C TIN & TP'!$A$3:$A$10005),0),MATCH('Reg 85'!$AG$11,'DMR 001C TIN & TP'!$A$2:$M$2,0))),"")} | AK14: {=_xlfn.IFNA((INDEX('DMR 001C TIN & TP'!$A$3:$M$10005,MATCH(('Reg 85'!$X$6&'Reg 85'!AK$10&'Reg 85'!$B14),('DMR 001C TIN & TP'!$E$3:$E$10005&'DMR 001C TIN & TP'!$B$3:$B$10005&'DMR 001C TIN & TP'!$A$3:$A$10005),0),MATCH('Reg 85'!$AG$11,'DMR 001C TIN & TP'!$A$2:$M$2,0))),"")} | AL14: {=_xlfn.IFNA((INDEX('DMR 001C TIN & TP'!$A$3:$M$10005,MATCH(('Reg 85'!$X$6&'Reg 85'!AL$10&'Reg 85'!$B14),('DMR 001C TIN & TP'!$E$3:$E$10005&'DMR 001C TIN & TP'!$B$3:$B$10005&'DMR 001C TIN & TP'!$A$3:$A$10005),0),MATCH('Reg 85'!$AG$11,'DMR 001C TIN & TP'!$A$2:$M$2,0))),"")} | AO14: =IFERROR(Q14+AF14,"") -> 6.5183897 | AP14: =IF(COUNT(IF((#REF!<=C14)*(#REF!>=D14)*(B14=EOMONTH(B14,0)),#REF!,""))=0,"",COUNT(IF((#REF!<=C14)*(#REF!>=D14)*(B14=EOMONTH(B14,0)),#REF!,""))) | AR14: {=_xlfn.IFNA((INDEX('DMR 001C TIN & TP'!$A$3:$M$10005,MATCH(('Reg 85'!$AQ$6&'Reg 85'!$AQ$10&'Reg 85'!$B14),('DMR 001C TIN & TP'!$E$3:$E$10005&'DMR 001C TIN & TP'!$B$3:$B$10005&'DMR 001C TIN & TP'!$A$3:$A$10005),0),MATCH('Reg 85'!$AR$11,'DMR 001C TIN & TP'!$A$2:$M$2,0))),"")} | AS14: {=_xlfn.IFNA((INDEX('DMR 001C TIN & TP'!$A$3:$M$10005,MATCH(('Reg 85'!$AQ$6&'Reg 85'!$AQ$10&'Reg 85'!$B14),('DMR 001C TIN & TP'!$E$3:$E$10005&'DMR 001C TIN & TP'!$B$3:$B$10005&'DMR 001C TIN & TP'!$A$3:$A$10005),0),MATCH('Reg 85'!$AS$11,'DMR 001C TIN & TP'!$A$2:$M$2,0))),"")} | AT14: =IFERROR(IF(VALUE(AS14)<VALUE(AR14),0,VALUE(AS14)),"") | AV14: {=_xlfn.IFNA((INDEX('DMR 001C TIN & TP'!$A$3:$M$10005,MATCH(('Reg 85'!$AQ$6&'Reg 85'!$AU$10&'Reg 85'!$B14),('DMR 001C TIN & TP'!$E$3:$E$10005&'DMR 001C TIN & TP'!$B$3:$B$10005&'DMR 001C TIN & TP'!$A$3:$A$10005),0),MATCH('Reg 85'!$AV$11,'DMR 001C TIN & TP'!$A$2:$M$2,0))),"")} | AW14: {=_xlfn.IFNA((INDEX('DMR 001C TIN & TP'!$A$3:$M$10005,MATCH(('Reg 85'!$AQ$6&'Reg 85'!$AU$10&'Reg 85'!$B14),('DMR 001C TIN & TP'!$E$3:$E$10005&'DMR 001C TIN & TP'!$B$3:$B$10005&'DMR 001C TIN & TP'!$A$3:$A$10005),0),MATCH('Reg 85'!$AW$11,'DMR 001C TIN & TP'!$A$2:$M$2,0))),"")} | AX14: =IFERROR(IF(VALUE(AW14)<VALUE(AV14),0,VALUE(AW14)),"") | AY14: =IFERROR(((AT14*$F14)+(AX14*$G14))/($H14),"") | AZ14: =IF(COUNT(IF((#REF!<=C14)*(#REF!>=D14)*(B14=EOMONTH(B14,0)),#REF!,""))=0,"",COUNT(IF((#REF!<=C14)*(#REF!>=D14)*(B14=EOMONTH(B14,0)),#REF!,""))) | BA14: {=_xlfn.IFNA((INDEX('DMR 001C TIN & TP'!$A$3:$M$10005,MATCH(('Reg 85'!$AQ$6&'Reg 85'!BA$10&'Reg 85'!$B14),('DMR 001C TIN & TP'!$E$3:$E$10005&'DMR 001C TIN & TP'!$B$3:$B$10005&'DMR 001C TIN & TP'!$A$3:$A$10005),0),MATCH('Reg 85'!$AG$11,'DMR 001C TIN & TP'!$A$2:$M$2,0))),"")} | BB14: {=_xlfn.IFNA((INDEX('DMR 001C TIN & TP'!$A$3:$M$10005,MATCH(('Reg 85'!$AQ$6&'Reg 85'!BB$10&'Reg 85'!$B14),('DMR 001C TIN & TP'!$E$3:$E$10005&'DMR 001C TIN & TP'!$B$3:$B$10005&'DMR 001C TIN & TP'!$A$3:$A$10005),0),MATCH('Reg 85'!$AG$11,'DMR 001C TIN & TP'!$A$2:$M$2,0))),"")} | BC14: {=_xlfn.IFNA((INDEX('DMR 001C TIN & TP'!$A$3:$M$10005,MATCH(('Reg 85'!$AQ$6&'Reg 85'!BC$10&'Reg 85'!$B14),('DMR 001C TIN & TP'!$E$3:$E$10005&'DMR 001C TIN & TP'!$B$3:$B$10005&'DMR 001C TIN & TP'!$A$3:$A$10005),0),MATCH('Reg 85'!$AG$11,'DMR 001C TIN & TP'!$A$2:$M$2,0))),"")} | BD14: {=_xlfn.IFNA((INDEX('DMR 001C TIN & TP'!$A$3:$M$10005,MATCH(('Reg 85'!$AQ$6&'Reg 85'!BD$10&'Reg 85'!$B14),('DMR 001C TIN & TP'!$E$3:$E$10005&'DMR 001C TIN & TP'!$B$3:$B$10005&'DMR 001C TIN & TP'!$A$3:$A$10005),0),MATCH('Reg 85'!$AG$11,'DMR 001C TIN & TP'!$A$2:$M$2,0))),"")} | BE14: {=_xlfn.IFNA((INDEX('DMR 001C TIN & TP'!$A$3:$M$10005,MATCH(('Reg 85'!$AQ$6&'Reg 85'!BE$10&'Reg 85'!$B14),('DMR 001C TIN & TP'!$E$3:$E$10005&'DMR 001C TIN & TP'!$B$3:$B$10005&'DMR 001C TIN & TP'!$A$3:$A$10005),0),MATCH('Reg 85'!$AG$11,'DMR 001C TIN & TP'!$A$2:$M$2,0))),"")} | BF14: {=_xlfn.IFNA((INDEX('DMR 001C TIN & TP'!$A$3:$M$10005,MATCH(('Reg 85'!$AQ$6&'Reg 85'!BF$10&'Reg 85'!$B14),('DMR 001C TIN & TP'!$E$3:$E$10005&'DMR 001C TIN & TP'!$B$3:$B$10005&'DMR 001C TIN & TP'!$A$3:$A$10005),0),MATCH('Reg 85'!$AG$11,'DMR 001C TIN & TP'!$A$2:$M$2,0))),"")}
A15: =TEXT(B15,"ddd") -> Tue | B15: =B14+1 -> 43347 | C15: =EOMONTH(B15,0) -> 43373 | D15: =EOMONTH(B15,-1)+1 -> 43344 | E15: =DAY(EOMONTH(B15,0)) -> 30 | F15: {=_xlfn.IFNA(INDEX('DMR Flows-Effluent'!$A$3:$F$9999,MATCH(($F$10&$B15),('DMR Flows-Effluent'!$B$3:$B$9999&'DMR Flows-Effluent'!$A$3:$A$9999),0),MATCH($F$8,'DMR Flows-Effluent'!$A$2:$F$2,0)),"")} -> 45.3051 | G15: {=_xlfn.IFNA(INDEX('DMR Flows-Effluent'!$A$3:$F$9999,MATCH(($G$10&$B15),('DMR Flows-Effluent'!$B$3:$B$9999&'DMR Flows-Effluent'!$A$3:$A$9999),0),MATCH($F$8,'DMR Flows-Effluent'!$A$2:$F$2,0)),"")} -> 68.3167 | H15: =SUM(F15:G15) -> 113.6218 | I15: =IFERROR(IF(L15<VALUE(J15),"<",""),"") | J15: {=_xlfn.IFNA((INDEX('DMR 001C TIN & TP'!$A$3:$M$10005,MATCH(('Reg 85'!$I$6:$Q$6&'Reg 85'!$I$10:$K$10&'Reg 85'!$B15),('DMR 001C TIN & TP'!$E$3:$E$10005&'DMR 001C TIN & TP'!$B$3:$B$10005&'DMR 001C TIN & TP'!$A$3:$A$10005),0),MATCH('Reg 85'!$J$11,'DMR 001C TIN & TP'!$A$2:$M$2,0))),"")} -> 0.15 | K15: {=_xlfn.IFNA((INDEX('DMR 001C TIN & TP'!$A$3:$M$10005,MATCH(('Reg 85'!$I$6:$Q$6&'Reg 85'!$I$10:$K$10&'Reg 85'!$B15),('DMR 001C TIN & TP'!$E$3:$E$10005&'DMR 001C TIN & TP'!$B$3:$B$10005&'DMR 001C TIN & TP'!$A$3:$A$10005),0),MATCH('Reg 85'!$K$11,'DMR 001C TIN & TP'!$A$2:$M$2,0))),"")} -> 0.25 | L15: =IFERROR(IF(VALUE(K15)<VALUE(J15),0,VALUE(K15)),"") -> 0.25 | M15: =IFERROR(IF(P15<VALUE(N15),"<",""),"") | N15: {=_xlfn.IFNA((INDEX('DMR 001C TIN & TP'!$A$3:$M$10005,MATCH(('Reg 85'!$I$6:$Q$6&'Reg 85'!$M$10&'Reg 85'!$B15),('DMR 001C TIN & TP'!$E$3:$E$10005&'DMR 001C TIN & TP'!$B$3:$B$10005&'DMR 001C TIN & TP'!$A$3:$A$10005),0),MATCH('Reg 85'!$N$11,'DMR 001C TIN & TP'!$A$2:$M$2,0))),"")} -> 0.15 | O15: {=_xlfn.IFNA((INDEX('DMR 001C TIN & TP'!$A$3:$M$10005,MATCH(('Reg 85'!$I$6:$Q$6&'Reg 85'!$M$10&'Reg 85'!$B15),('DMR 001C TIN & TP'!$E$3:$E$10005&'DMR 001C TIN & TP'!$B$3:$B$10005&'DMR 001C TIN & TP'!$A$3:$A$10005),0),MATCH('Reg 85'!$O$11,'DMR 001C TIN & TP'!$A$2:$M$2,0))),"")} -> 0.34 | P15: =IFERROR(IF(VALUE(O15)<VALUE(N15),0,VALUE(O15)),"") -> 0.34 | Q15: {=IFERROR(((L15*$F15)+(P15*$G15))/($H15),"")} -> 0.30411376 | R15: {=_xlfn.IFNA((INDEX('DMR 001C TIN & TP'!$A$3:$M$10005,MATCH(('Reg 85'!$I$6:$Q$6&'Reg 85'!R$10&'Reg 85'!$B15),('DMR 001C TIN & TP'!$E$3:$E$10005&'DMR 001C TIN & TP'!$B$3:$B$10005&'DMR 001C TIN & TP'!$A$3:$A$10005),0),MATCH('Reg 85'!$O$11,'DMR 001C TIN & TP'!$A$2:$M$2,0))),"")} | S15: {=_xlfn.IFNA((INDEX('DMR 001C TIN & TP'!$A$3:$M$10005,MATCH(('Reg 85'!$I$6:$Q$6&'Reg 85'!S$10&'Reg 85'!$B15),('DMR 001C TIN & TP'!$E$3:$E$10005&'DMR 001C TIN & TP'!$B$3:$B$10005&'DMR 001C TIN & TP'!$A$3:$A$10005),0),MATCH('Reg 85'!$O$11,'DMR 001C TIN & TP'!$A$2:$M$2,0))),"")} | T15: {=_xlfn.IFNA((INDEX('DMR 001C TIN & TP'!$A$3:$M$10005,MATCH(('Reg 85'!$I$6:$Q$6&'Reg 85'!T$10&'Reg 85'!$B15),('DMR 001C TIN & TP'!$E$3:$E$10005&'DMR 001C TIN & TP'!$B$3:$B$10005&'DMR 001C TIN & TP'!$A$3:$A$10005),0),MATCH('Reg 85'!$O$11,'DMR 001C TIN & TP'!$A$2:$M$2,0))),"")} | U15: {=_xlfn.IFNA((INDEX('DMR 001C TIN & TP'!$A$3:$M$10005,MATCH(('Reg 85'!$I$6:$Q$6&'Reg 85'!U$10&'Reg 85'!$B15),('DMR 001C TIN & TP'!$E$3:$E$10005&'DMR 001C TIN & TP'!$B$3:$B$10005&'DMR 001C TIN & TP'!$A$3:$A$10005),0),MATCH('Reg 85'!$O$11,'DMR 001C TIN & TP'!$A$2:$M$2,0))),"")} | V15: {=_xlfn.IFNA((INDEX('DMR 001C TIN & TP'!$A$3:$M$10005,MATCH(('Reg 85'!$I$6:$Q$6&'Reg 85'!V$10&'Reg 85'!$B15),('DMR 001C TIN & TP'!$E$3:$E$10005&'DMR 001C TIN & TP'!$B$3:$B$10005&'DMR 001C TIN & TP'!$A$3:$A$10005),0),MATCH('Reg 85'!$O$11,'DMR 001C TIN & TP'!$A$2:$M$2,0))),"")} | W15: {=_xlfn.IFNA((INDEX('DMR 001C TIN & TP'!$A$3:$M$10005,MATCH(('Reg 85'!$I$6:$Q$6&'Reg 85'!W$10&'Reg 85'!$B15),('DMR 001C TIN & TP'!$E$3:$E$10005&'DMR 001C TIN & TP'!$B$3:$B$10005&'DMR 001C TIN & TP'!$A$3:$A$10005),0),MATCH('Reg 85'!$O$11,'DMR 001C TIN & TP'!$A$2:$M$2,0))),"")} | X15: =IFERROR(IF(AA15<VALUE(Y15),"<",""),"") | Y15: {=_xlfn.IFNA((INDEX('DMR 001C TIN & TP'!$A$3:$M$10005,MATCH(('Reg 85'!$X$6&'Reg 85'!$X$10&'Reg 85'!$B15),('DMR 001C TIN & TP'!$E$3:$E$10005&'DMR 001C TIN & TP'!$B$3:$B$10005&'DMR 001C TIN & TP'!$A$3:$A$10005),0),MATCH('Reg 85'!$Y$11,'DMR 001C TIN & TP'!$A$2:$M$2,0))),"")} -> 0.18 | Z15: {=_xlfn.IFNA((INDEX('DMR 001C TIN & TP'!$A$3:$M$10005,MATCH(('Reg 85'!$X$6&'Reg 85'!$X$10&'Reg 85'!$B15),('DMR 001C TIN & TP'!$E$3:$E$10005&'DMR 001C TIN & TP'!$B$3:$B$10005&'DMR 001C TIN & TP'!$A$3:$A$10005),0),MATCH('Reg 85'!$Z$11,'DMR 001C TIN & TP'!$A$2:$M$2,0))),"")} -> 4.59 | AA15: =IFERROR(IF(VALUE(Z15)<VALUE(Y15),0,VALUE(Z15)),"") -> 4.59 | AB15: =IFERROR(IF(AE15<VALUE(AC15),"<",""),"") | AC15: {=_xlfn.IFNA((INDEX('DMR 001C TIN & TP'!$A$3:$M$10005,MATCH(('Reg 85'!$X$6&'Reg 85'!$AB$10&'Reg 85'!$B15),('DMR 001C TIN & TP'!$E$3:$E$10005&'DMR 001C TIN & TP'!$B$3:$B$10005&'DMR 001C TIN & TP'!$A$3:$A$10005),0),MATCH('Reg 85'!$AC$11,'DMR 001C TIN & TP'!$A$2:$M$2,0))),"")} -> 0.06 | AD15: {=_xlfn.IFNA((INDEX('DMR 001C TIN & TP'!$A$3:$M$10005,MATCH(('Reg 85'!$X$6&'Reg 85'!$AB$10&'Reg 85'!$B15),('DMR 001C TIN & TP'!$E$3:$E$10005&'DMR 001C TIN & TP'!$B$3:$B$10005&'DMR 001C TIN & TP'!$A$3:$A$10005),0),MATCH('Reg 85'!$AD$11,'DMR 001C TIN & TP'!$A$2:$M$2,0))),"")} -> 5.18 | AE15: =IFERROR(IF(VALUE(AD15)<VALUE(AC15),0,VALUE(AD15)),"") -> 5.18 | AF15: =IFERROR(((AA15*$F15)+(AE15*$G15))/($H15),"") -> 4.9447458 | AG15: {=_xlfn.IFNA((INDEX('DMR 001C TIN & TP'!$A$3:$M$10005,MATCH(('Reg 85'!$X$6&'Reg 85'!AG$10&'Reg 85'!$B15),('DMR 001C TIN & TP'!$E$3:$E$10005&'DMR 001C TIN & TP'!$B$3:$B$10005&'DMR 001C TIN & TP'!$A$3:$A$10005),0),MATCH('Reg 85'!$AG$11,'DMR 001C TIN & TP'!$A$2:$M$2,0))),"")} | AH15: {=_xlfn.IFNA((INDEX('DMR 001C TIN & TP'!$A$3:$M$10005,MATCH(('Reg 85'!$X$6&'Reg 85'!AH$10&'Reg 85'!$B15),('DMR 001C TIN & TP'!$E$3:$E$10005&'DMR 001C TIN & TP'!$B$3:$B$10005&'DMR 001C TIN & TP'!$A$3:$A$10005),0),MATCH('Reg 85'!$AG$11,'DMR 001C TIN & TP'!$A$2:$M$2,0))),"")} | AI15: {=_xlfn.IFNA((INDEX('DMR 001C TIN & TP'!$A$3:$M$10005,MATCH(('Reg 85'!$X$6&'Reg 85'!AI$10&'Reg 85'!$B15),('DMR 001C TIN & TP'!$E$3:$E$10005&'DMR 001C TIN & TP'!$B$3:$B$10005&'DMR 001C TIN & TP'!$A$3:$A$10005),0),MATCH('Reg 85'!$AG$11,'DMR 001C TIN & TP'!$A$2:$M$2,0))),"")} | AJ15: {=_xlfn.IFNA((INDEX('DMR 001C TIN & TP'!$A$3:$M$10005,MATCH(('Reg 85'!$X$6&'Reg 85'!AJ$10&'Reg 85'!$B15),('DMR 001C TIN & TP'!$E$3:$E$10005&'DMR 001C TIN & TP'!$B$3:$B$10005&'DMR 001C TIN & TP'!$A$3:$A$10005),0),MATCH('Reg 85'!$AG$11,'DMR 001C TIN & TP'!$A$2:$M$2,0))),"")} | AK15: {=_xlfn.IFNA((INDEX('DMR 001C TIN & TP'!$A$3:$M$10005,MATCH(('Reg 85'!$X$6&'Reg 85'!AK$10&'Reg 85'!$B15),('DMR 001C TIN & TP'!$E$3:$E$10005&'DMR 001C TIN & TP'!$B$3:$B$10005&'DMR 001C TIN & TP'!$A$3:$A$10005),0),MATCH('Reg 85'!$AG$11,'DMR 001C TIN & TP'!$A$2:$M$2,0))),"")} | AL15: {=_xlfn.IFNA((INDEX('DMR 001C TIN & TP'!$A$3:$M$10005,MATCH(('Reg 85'!$X$6&'Reg 85'!AL$10&'Reg 85'!$B15),('DMR 001C TIN & TP'!$E$3:$E$10005&'DMR 001C TIN & TP'!$B$3:$B$10005&'DMR 001C TIN & TP'!$A$3:$A$10005),0),MATCH('Reg 85'!$AG$11,'DMR 001C TIN & TP'!$A$2:$M$2,0))),"")} | AO15: =IFERROR(Q15+AF15,"") -> 5.2488595 | AP15: =IF(COUNT(IF((#REF!<=C15)*(#REF!>=D15)*(B15=EOMONTH(B15,0)),#REF!,""))=0,"",COUNT(IF((#REF!<=C15)*(#REF!>=D15)*(B15=EOMONTH(B15,0)),#REF!,""))) | AR15: {=_xlfn.IFNA((INDEX('DMR 001C TIN & TP'!$A$3:$M$10005,MATCH(('Reg 85'!$AQ$6&'Reg 85'!$AQ$10&'Reg 85'!$B15),('DMR 001C TIN & TP'!$E$3:$E$10005&'DMR 001C TIN & TP'!$B$3:$B$10005&'DMR 001C TIN & TP'!$A$3:$A$10005),0),MATCH('Reg 85'!$AR$11,'DMR 001C TIN & TP'!$A$2:$M$2,0))),"")} | AS15: {=_xlfn.IFNA((INDEX('DMR 001C TIN & TP'!$A$3:$M$10005,MATCH(('Reg 85'!$AQ$6&'Reg 85'!$AQ$10&'Reg 85'!$B15),('DMR 001C TIN & TP'!$E$3:$E$10005&'DMR 001C TIN & TP'!$B$3:$B$10005&'DMR 001C TIN & TP'!$A$3:$A$10005),0),MATCH('Reg 85'!$AS$11,'DMR 001C TIN & TP'!$A$2:$M$2,0))),"")} | AT15: =IFERROR(IF(VALUE(AS15)<VALUE(AR15),0,VALUE(AS15)),"") | AV15: {=_xlfn.IFNA((INDEX('DMR 001C TIN & TP'!$A$3:$M$10005,MATCH(('Reg 85'!$AQ$6&'Reg 85'!$AU$10&'Reg 85'!$B15),('DMR 001C TIN & TP'!$E$3:$E$10005&'DMR 001C TIN & TP'!$B$3:$B$10005&'DMR 001C TIN & TP'!$A$3:$A$10005),0),MATCH('Reg 85'!$AV$11,'DMR 001C TIN & TP'!$A$2:$M$2,0))),"")} | AW15: {=_xlfn.IFNA((INDEX('DMR 001C TIN & TP'!$A$3:$M$10005,MATCH(('Reg 85'!$AQ$6&'Reg 85'!$AU$10&'Reg 85'!$B15),('DMR 001C TIN & TP'!$E$3:$E$10005&'DMR 001C TIN & TP'!$B$3:$B$10005&'DMR 001C TIN & TP'!$A$3:$A$10005),0),MATCH('Reg 85'!$AW$11,'DMR 001C TIN & TP'!$A$2:$M$2,0))),"")} | AX15: =IFERROR(IF(VALUE(AW15)<VALUE(AV15),0,VALUE(AW15)),"") | AY15: =IFERROR(((AT15*$F15)+(AX15*$G15))/($H15),"") | AZ15: =IF(COUNT(IF((#REF!<=C15)*(#REF!>=D15)*(B15=EOMONTH(B15,0)),#REF!,""))=0,"",COUNT(IF((#REF!<=C15)*(#REF!>=D15)*(B15=EOMONTH(B15,0)),#REF!,""))) | BA15: {=_xlfn.IFNA((INDEX('DMR 001C TIN & TP'!$A$3:$M$10005,MATCH(('Reg 85'!$AQ$6&'Reg 85'!BA$10&'Reg 85'!$B15),('DMR 001C TIN & TP'!$E$3:$E$10005&'DMR 001C TIN & TP'!$B$3:$B$10005&'DMR 001C TIN & TP'!$A$3:$A$10005),0),MATCH('Reg 85'!$AG$11,'DMR 001C TIN & TP'!$A$2:$M$2,0))),"")} | BB15: {=_xlfn.IFNA((INDEX('DMR 001C TIN & TP'!$A$3:$M$10005,MATCH(('Reg 85'!$AQ$6&'Reg 85'!BB$10&'Reg 85'!$B15),('DMR 001C TIN & TP'!$E$3:$E$10005&'DMR 001C TIN & TP'!$B$3:$B$10005&'DMR 001C TIN & TP'!$A$3:$A$10005),0),MATCH('Reg 85'!$AG$11,'DMR 001C TIN & TP'!$A$2:$M$2,0))),"")} | BC15: {=_xlfn.IFNA((INDEX('DMR 001C TIN & TP'!$A$3:$M$10005,MATCH(('Reg 85'!$AQ$6&'Reg 85'!BC$10&'Reg 85'!$B15),('DMR 001C TIN & TP'!$E$3:$E$10005&'DMR 001C TIN & TP'!$B$3:$B$10005&'DMR 001C TIN & TP'!$A$3:$A$10005),0),MATCH('Reg 85'!$AG$11,'DMR 001C TIN & TP'!$A$2:$M$2,0))),"")} | BD15: {=_xlfn.IFNA((INDEX('DMR 001C TIN & TP'!$A$3:$M$10005,MATCH(('Reg 85'!$AQ$6&'Reg 85'!BD$10&'Reg 85'!$B15),('DMR 001C TIN & TP'!$E$3:$E$10005&'DMR 001C TIN & TP'!$B$3:$B$10005&'DMR 001C TIN & TP'!$A$3:$A$10005),0),MATCH('Reg 85'!$AG$11,'DMR 001C TIN & TP'!$A$2:$M$2,0))),"")} | BE15: {=_xlfn.IFNA((INDEX('DMR 001C TIN & TP'!$A$3:$M$10005,MATCH(('Reg 85'!$AQ$6&'Reg 85'!BE$10&'Reg 85'!$B15),('DMR 001C TIN & TP'!$E$3:$E$10005&'DMR 001C TIN & TP'!$B$3:$B$10005&'DMR 001C TIN & TP'!$A$3:$A$10005),0),MATCH('Reg 85'!$AG$11,'DMR 001C TIN & TP'!$A$2:$M$2,0))),"")} | BF15: {=_xlfn.IFNA((INDEX('DMR 001C TIN & TP'!$A$3:$M$10005,MATCH(('Reg 85'!$AQ$6&'Reg 85'!BF$10&'Reg 85'!$B15),('DMR 001C TIN & TP'!$E$3:$E$10005&'DMR 001C TIN & TP'!$B$3:$B$10005&'DMR 001C TIN & TP'!$A$3:$A$10005),0),MATCH('Reg 85'!$AG$11,'DMR 001C TIN & TP'!$A$2:$M$2,0))),"")}
A16: =TEXT(B16,"ddd") -> Wed | B16: =B15+1 -> 43348 | C16: =EOMONTH(B16,0) -> 43373 | D16: =EOMONTH(B16,-1)+1 -> 43344 | E16: =DAY(EOMONTH(B16,0)) -> 30 | F16: {=_xlfn.IFNA(INDEX('DMR Flows-Effluent'!$A$3:$F$9999,MATCH(($F$10&$B16),('DMR Flows-Effluent'!$B$3:$B$9999&'DMR Flows-Effluent'!$A$3:$A$9999),0),MATCH($F$8,'DMR Flows-Effluent'!$A$2:$F$2,0)),"")} -> 60.033 | G16: {=_xlfn.IFNA(INDEX('DMR Flows-Effluent'!$A$3:$F$9999,MATCH(($G$10&$B16),('DMR Flows-Effluent'!$B$3:$B$9999&'DMR Flows-Effluent'!$A$3:$A$9999),0),MATCH($F$8,'DMR Flows-Effluent'!$A$2:$F$2,0)),"")} -> 76.2002 | H16: =SUM(F16:G16) -> 136.2332 | I16: =IFERROR(IF(L16<VALUE(J16),"<",""),"") | J16: {=_xlfn.IFNA((INDEX('DMR 001C TIN & TP'!$A$3:$M$10005,MATCH(('Reg 85'!$I$6:$Q$6&'Reg 85'!$I$10:$K$10&'Reg 85'!$B16),('DMR 001C TIN & TP'!$E$3:$E$10005&'DMR 001C TIN & TP'!$B$3:$B$10005&'DMR 001C TIN & TP'!$A$3:$A$10005),0),MATCH('Reg 85'!$J$11,'DMR 001C TIN & TP'!$A$2:$M$2,0))),"")} -> 0.15 | K16: {=_xlfn.IFNA((INDEX('DMR 001C TIN & TP'!$A$3:$M$10005,MATCH(('Reg 85'!$I$6:$Q$6&'Reg 85'!$I$10:$K$10&'Reg 85'!$B16),('DMR 001C TIN & TP'!$E$3:$E$10005&'DMR 001C TIN & TP'!$B$3:$B$10005&'DMR 001C TIN & TP'!$A$3:$A$10005),0),MATCH('Reg 85'!$K$11,'DMR 001C TIN & TP'!$A$2:$M$2,0))),"")} -> 0.62 | L16: =IFERROR(IF(VALUE(K16)<VALUE(J16),0,VALUE(K16)),"") -> 0.62 | M16: =IFERROR(IF(P16<VALUE(N16),"<",""),"") | N16: {=_xlfn.IFNA((INDEX('DMR 001C TIN & TP'!$A$3:$M$10005,MATCH(('Reg 85'!$I$6:$Q$6&'Reg 85'!$M$10&'Reg 85'!$B16),('DMR 001C TIN & TP'!$E$3:$E$10005&'DMR 001C TIN & TP'!$B$3:$B$10005&'DMR 001C TIN & TP'!$A$3:$A$10005),0),MATCH('Reg 85'!$N$11,'DMR 001C TIN & TP'!$A$2:$M$2,0))),"")} -> 0.15 | O16: {=_xlfn.IFNA((INDEX('DMR 001C TIN & TP'!$A$3:$M$10005,MATCH(('Reg 85'!$I$6:$Q$6&'Reg 85'!$M$10&'Reg 85'!$B16),('DMR 001C TIN & TP'!$E$3:$E$10005&'DMR 001C TIN & TP'!$B$3:$B$10005&'DMR 001C TIN & TP'!$A$3:$A$10005),0),MATCH('Reg 85'!$O$11,'DMR 001C TIN & TP'!$A$2:$M$2,0))),"")} -> 0.38 | P16: =IFERROR(IF(VALUE(O16)<VALUE(N16),0,VALUE(O16)),"") -> 0.38 | Q16: {=IFERROR(((L16*$F16)+(P16*$G16))/($H16),"")} -> 0.48575924 | R16: {=_xlfn.IFNA((INDEX('DMR 001C TIN & TP'!$A$3:$M$10005,MATCH(('Reg 85'!$I$6:$Q$6&'Reg 85'!R$10&'Reg 85'!$B16),('DMR 001C TIN & TP'!$E$3:$E$10005&'DMR 001C TIN & TP'!$B$3:$B$10005&'DMR 001C TIN & TP'!$A$3:$A$10005),0),MATCH('Reg 85'!$O$11,'DMR 001C TIN & TP'!$A$2:$M$2,0))),"")} | S16: {=_xlfn.IFNA((INDEX('DMR 001C TIN & TP'!$A$3:$M$10005,MATCH(('Reg 85'!$I$6:$Q$6&'Reg 85'!S$10&'Reg 85'!$B16),('DMR 001C TIN & TP'!$E$3:$E$10005&'DMR 001C TIN & TP'!$B$3:$B$10005&'DMR 001C TIN & TP'!$A$3:$A$10005),0),MATCH('Reg 85'!$O$11,'DMR 001C TIN & TP'!$A$2:$M$2,0))),"")} | T16: {=_xlfn.IFNA((INDEX('DMR 001C TIN & TP'!$A$3:$M$10005,MATCH(('Reg 85'!$I$6:$Q$6&'Reg 85'!T$10&'Reg 85'!$B16),('DMR 001C TIN & TP'!$E$3:$E$10005&'DMR 001C TIN & TP'!$B$3:$B$10005&'DMR 001C TIN & TP'!$A$3:$A$10005),0),MATCH('Reg 85'!$O$11,'DMR 001C TIN & TP'!$A$2:$M$2,0))),"")} | U16: {=_xlfn.IFNA((INDEX('DMR 001C TIN & TP'!$A$3:$M$10005,MATCH(('Reg 85'!$I$6:$Q$6&'Reg 85'!U$10&'Reg 85'!$B16),('DMR 001C TIN & TP'!$E$3:$E$10005&'DMR 001C TIN & TP'!$B$3:$B$10005&'DMR 001C TIN & TP'!$A$3:$A$10005),0),MATCH('Reg 85'!$O$11,'DMR 001C TIN & TP'!$A$2:$M$2,0))),"")} | V16: {=_xlfn.IFNA((INDEX('DMR 001C TIN & TP'!$A$3:$M$10005,MATCH(('Reg 85'!$I$6:$Q$6&'Reg 85'!V$10&'Reg 85'!$B16),('DMR 001C TIN & TP'!$E$3:$E$10005&'DMR 001C TIN & TP'!$B$3:$B$10005&'DMR 001C TIN & TP'!$A$3:$A$10005),0),MATCH('Reg 85'!$O$11,'DMR 001C TIN & TP'!$A$2:$M$2,0))),"")} | W16: {=_xlfn.IFNA((INDEX('DMR 001C TIN & TP'!$A$3:$M$10005,MATCH(('Reg 85'!$I$6:$Q$6&'Reg 85'!W$10&'Reg 85'!$B16),('DMR 001C TIN & TP'!$E$3:$E$10005&'DMR 001C TIN & TP'!$B$3:$B$10005&'DMR 001C TIN & TP'!$A$3:$A$10005),0),MATCH('Reg 85'!$O$11,'DMR 001C TIN & TP'!$A$2:$M$2,0))),"")} | X16: =IFERROR(IF(AA16<VALUE(Y16),"<",""),"") | Y16: {=_xlfn.IFNA((INDEX('DMR 001C TIN & TP'!$A$3:$M$10005,MATCH(('Reg 85'!$X$6&'Reg 85'!$X$10&'Reg 85'!$B16),('DMR 001C TIN & TP'!$E$3:$E$10005&'DMR 001C TIN & TP'!$B$3:$B$10005&'DMR 001C TIN & TP'!$A$3:$A$10005),0),MATCH('Reg 85'!$Y$11,'DMR 001C TIN & TP'!$A$2:$M$2,0))),"")} -> 0.18 | Z16: {=_xlfn.IFNA((INDEX('DMR 001C TIN & TP'!$A$3:$M$10005,MATCH(('Reg 85'!$X$6&'Reg 85'!$X$10&'Reg 85'!$B16),('DMR 001C TIN & TP'!$E$3:$E$10005&'DMR 001C TIN & TP'!$B$3:$B$10005&'DMR 001C TIN & TP'!$A$3:$A$10005),0),MATCH('Reg 85'!$Z$11,'DMR 001C TIN & TP'!$A$2:$M$2,0))),"")} -> 4.44 | AA16: =IFERROR(IF(VALUE(Z16)<VALUE(Y16),0,VALUE(Z16)),"") -> 4.44 | AB16: =IFERROR(IF(AE16<VALUE(AC16),"<",""),"") | AC16: {=_xlfn.IFNA((INDEX('DMR 001C TIN & TP'!$A$3:$M$10005,MATCH(('Reg 85'!$X$6&'Reg 85'!$AB$10&'Reg 85'!$B16),('DMR 001C TIN & TP'!$E$3:$E$10005&'DMR 001C TIN & TP'!$B$3:$B$10005&'DMR 001C TIN & TP'!$A$3:$A$10005),0),MATCH('Reg 85'!$AC$11,'DMR 001C TIN & TP'!$A$2:$M$2,0))),"")} -> 0.06 | AD16: {=_xlfn.IFNA((INDEX('DMR 001C TIN & TP'!$A$3:$M$10005,MATCH(('Reg 85'!$X$6&'Reg 85'!$AB$10&'Reg 85'!$B16),('DMR 001C TIN & TP'!$E$3:$E$10005&'DMR 001C TIN & TP'!$B$3:$B$10005&'DMR 001C TIN & TP'!$A$3:$A$10005),0),MATCH('Reg 85'!$AD$11,'DMR 001C TIN & TP'!$A$2:$M$2,0))),"")} -> 5.01 | AE16: =IFERROR(IF(VALUE(AD16)<VALUE(AC16),0,VALUE(AD16)),"") -> 5.01 | AF16: =IFERROR(((AA16*$F16)+(AE16*$G16))/($H16),"") -> 4.7588218 | AG16: {=_xlfn.IFNA((INDEX('DMR 001C TIN & TP'!$A$3:$M$10005,MATCH(('Reg 85'!$X$6&'Reg 85'!AG$10&'Reg 85'!$B16),('DMR 001C TIN & TP'!$E$3:$E$10005&'DMR 001C TIN & TP'!$B$3:$B$10005&'DMR 001C TIN & TP'!$A$3:$A$10005),0),MATCH('Reg 85'!$AG$11,'DMR 001C TIN & TP'!$A$2:$M$2,0))),"")} | AH16: {=_xlfn.IFNA((INDEX('DMR 001C TIN & TP'!$A$3:$M$10005,MATCH(('Reg 85'!$X$6&'Reg 85'!AH$10&'Reg 85'!$B16),('DMR 001C TIN & TP'!$E$3:$E$10005&'DMR 001C TIN & TP'!$B$3:$B$10005&'DMR 001C TIN & TP'!$A$3:$A$10005),0),MATCH('Reg 85'!$AG$11,'DMR 001C TIN & TP'!$A$2:$M$2,0))),"")} | AI16: {=_xlfn.IFNA((INDEX('DMR 001C TIN & TP'!$A$3:$M$10005,MATCH(('Reg 85'!$X$6&'Reg 85'!AI$10&'Reg 85'!$B16),('DMR 001C TIN & TP'!$E$3:$E$10005&'DMR 001C TIN & TP'!$B$3:$B$10005&'DMR 001C TIN & TP'!$A$3:$A$10005),0),MATCH('Reg 85'!$AG$11,'DMR 001C TIN & TP'!$A$2:$M$2,0))),"")} | AJ16: {=_xlfn.IFNA((INDEX('DMR 001C TIN & TP'!$A$3:$M$10005,MATCH(('Reg 85'!$X$6&'Reg 85'!AJ$10&'Reg 85'!$B16),('DMR 001C TIN & TP'!$E$3:$E$10005&'DMR 001C TIN & TP'!$B$3:$B$10005&'DMR 001C TIN & TP'!$A$3:$A$10005),0),MATCH('Reg 85'!$AG$11,'DMR 001C TIN & TP'!$A$2:$M$2,0))),"")} | AK16: {=_xlfn.IFNA((INDEX('DMR 001C TIN & TP'!$A$3:$M$10005,MATCH(('Reg 85'!$X$6&'Reg 85'!AK$10&'Reg 85'!$B16),('DMR 001C TIN & TP'!$E$3:$E$10005&'DMR 001C TIN & TP'!$B$3:$B$10005&'DMR 001C TIN & TP'!$A$3:$A$10005),0),MATCH('Reg 85'!$AG$11,'DMR 001C TIN & TP'!$A$2:$M$2,0))),"")} | AL16: {=_xlfn.IFNA((INDEX('DMR 001C TIN & TP'!$A$3:$M$10005,MATCH(('Reg 85'!$X$6&'Reg 85'!AL$10&'Reg 85'!$B16),('DMR 001C TIN & TP'!$E$3:$E$10005&'DMR 001C TIN & TP'!$B$3:$B$10005&'DMR 001C TIN & TP'!$A$3:$A$10005),0),MATCH('Reg 85'!$AG$11,'DMR 001C TIN & TP'!$A$2:$M$2,0))),"")} | AO16: =IFERROR(Q16+AF16,"") -> 5.244581 | AP16: =IF(COUNT(IF((#REF!<=C16)*(#REF!>=D16)*(B16=EOMONTH(B16,0)),#REF!,""))=0,"",COUNT(IF((#REF!<=C16)*(#REF!>=D16)*(B16=EOMONTH(B16,0)),#REF!,""))) | AR16: {=_xlfn.IFNA((INDEX('DMR 001C TIN & TP'!$A$3:$M$10005,MATCH(('Reg 85'!$AQ$6&'Reg 85'!$AQ$10&'Reg 85'!$B16),('DMR 001C TIN & TP'!$E$3:$E$10005&'DMR 001C TIN & TP'!$B$3:$B$10005&'DMR 001C TIN & TP'!$A$3:$A$10005),0),MATCH('Reg 85'!$AR$11,'DMR 001C TIN & TP'!$A$2:$M$2,0))),"")} | AS16: {=_xlfn.IFNA((INDEX('DMR 001C TIN & TP'!$A$3:$M$10005,MATCH(('Reg 85'!$AQ$6&'Reg 85'!$AQ$10&'Reg 85'!$B16),('DMR 001C TIN & TP'!$E$3:$E$10005&'DMR 001C TIN & TP'!$B$3:$B$10005&'DMR 001C TIN & TP'!$A$3:$A$10005),0),MATCH('Reg 85'!$AS$11,'DMR 001C TIN & TP'!$A$2:$M$2,0))),"")} | AT16: =IFERROR(IF(VALUE(AS16)<VALUE(AR16),0,VALUE(AS16)),"") | AV16: {=_xlfn.IFNA((INDEX('DMR 001C TIN & TP'!$A$3:$M$10005,MATCH(('Reg 85'!$AQ$6&'Reg 85'!$AU$10&'Reg 85'!$B16),('DMR 001C TIN & TP'!$E$3:$E$10005&'DMR 001C TIN & TP'!$B$3:$B$10005&'DMR 001C TIN & TP'!$A$3:$A$10005),0),MATCH('Reg 85'!$AV$11,'DMR 001C TIN & TP'!$A$2:$M$2,0))),"")} | AW16: {=_xlfn.IFNA((INDEX('DMR 001C TIN & TP'!$A$3:$M$10005,MATCH(('Reg 85'!$AQ$6&'Reg 85'!$AU$10&'Reg 85'!$B16),('DMR 001C TIN & TP'!$E$3:$E$10005&'DMR 001C TIN & TP'!$B$3:$B$10005&'DMR 001C TIN & TP'!$A$3:$A$10005),0),MATCH('Reg 85'!$AW$11,'DMR 001C TIN & TP'!$A$2:$M$2,0))),"")} | AX16: =IFERROR(IF(VALUE(AW16)<VALUE(AV16),0,VALUE(AW16)),"") | AY16: =IFERROR(((AT16*$F16)+(AX16*$G16))/($H16),"") | AZ16: =IF(COUNT(IF((#REF!<=C16)*(#REF!>=D16)*(B16=EOMONTH(B16,0)),#REF!,""))=0,"",COUNT(IF((#REF!<=C16)*(#REF!>=D16)*(B16=EOMONTH(B16,0)),#REF!,""))) | BA16: {=_xlfn.IFNA((INDEX('DMR 001C TIN & TP'!$A$3:$M$10005,MATCH(('Reg 85'!$AQ$6&'Reg 85'!BA$10&'Reg 85'!$B16),('DMR 001C TIN & TP'!$E$3:$E$10005&'DMR 001C TIN & TP'!$B$3:$B$10005&'DMR 001C TIN & TP'!$A$3:$A$10005),0),MATCH('Reg 85'!$AG$11,'DMR 001C TIN & TP'!$A$2:$M$2,0))),"")} | BB16: {=_xlfn.IFNA((INDEX('DMR 001C TIN & TP'!$A$3:$M$10005,MATCH(('Reg 85'!$AQ$6&'Reg 85'!BB$10&'Reg 85'!$B16),('DMR 001C TIN & TP'!$E$3:$E$10005&'DMR 001C TIN & TP'!$B$3:$B$10005&'DMR 001C TIN & TP'!$A$3:$A$10005),0),MATCH('Reg 85'!$AG$11,'DMR 001C TIN & TP'!$A$2:$M$2,0))),"")} | BC16: {=_xlfn.IFNA((INDEX('DMR 001C TIN & TP'!$A$3:$M$10005,MATCH(('Reg 85'!$AQ$6&'Reg 85'!BC$10&'Reg 85'!$B16),('DMR 001C TIN & TP'!$E$3:$E$10005&'DMR 001C TIN & TP'!$B$3:$B$10005&'DMR 001C TIN & TP'!$A$3:$A$10005),0),MATCH('Reg 85'!$AG$11,'DMR 001C TIN & TP'!$A$2:$M$2,0))),"")} | BD16: {=_xlfn.IFNA((INDEX('DMR 001C TIN & TP'!$A$3:$M$10005,MATCH(('Reg 85'!$AQ$6&'Reg 85'!BD$10&'Reg 85'!$B16),('DMR 001C TIN & TP'!$E$3:$E$10005&'DMR 001C TIN & TP'!$B$3:$B$10005&'DMR 001C TIN & TP'!$A$3:$A$10005),0),MATCH('Reg 85'!$AG$11,'DMR 001C TIN & TP'!$A$2:$M$2,0))),"")} | BE16: {=_xlfn.IFNA((INDEX('DMR 001C TIN & TP'!$A$3:$M$10005,MATCH(('Reg 85'!$AQ$6&'Reg 85'!BE$10&'Reg 85'!$B16),('DMR 001C TIN & TP'!$E$3:$E$10005&'DMR 001C TIN & TP'!$B$3:$B$10005&'DMR 001C TIN & TP'!$A$3:$A$10005),0),MATCH('Reg 85'!$AG$11,'DMR 001C TIN & TP'!$A$2:$M$2,0))),"")} | BF16: {=_xlfn.IFNA((INDEX('DMR 001C TIN & TP'!$A$3:$M$10005,MATCH(('Reg 85'!$AQ$6&'Reg 85'!BF$10&'Reg 85'!$B16),('DMR 001C TIN & TP'!$E$3:$E$10005&'DMR 001C TIN & TP'!$B$3:$B$10005&'DMR 001C TIN & TP'!$A$3:$A$10005),0),MATCH('Reg 85'!$AG$11,'DMR 001C TIN & TP'!$A$2:$M$2,0))),"")}
